Workbook

Sheet Planilha6
A1: Linha do Tempo | B1: Valores | C1: Previsão | D1: Limite de Confiança Inferior | E1: Limite de Confiança Superior
A2: 45658 | B2: 159260.53
A3: 45689 | B3: 205465.7
A4: 45717 | B4: 212696.97
A5: 45748 | B5: 225882.05
A6: 45778 | B6: 252020.4
A7: 45809 | B7: 159826.26
A8: 45839 | B8: 205248.67
A9: 45870 | B9: 183735.51
A10: 45901 | B10: 202938.1
A11: 45931 | B11: 178379.29
A12: 45962 | B12: 184310.95
A13: 45992 | B13: 198779.59
... A16: 46082 | B16: 183424.12
A17: 46113 | B17: 214380.68 | C17: 214380.68 | D17: 214380.68 | E17: 214380.68
A18: 46143 | C18: =_xlfn.FORECAST.ETS(A18,$B$2:$B$17,$A$2:$A$17,1,1) -> 184769.44 | D18: =C18-_xlfn.FORECAST.ETS.CONFINT(A18,$B$2:$B$17,$A$2:$A$17,0.95,1,1) -> 113467.07 | E18: =C18+_xlfn.FORECAST.ETS.CONFINT(A18,$B$2:$B$17,$A$2:$A$17,0.95,1,1) -> 256071.8
A19: 46174 | C19: =_xlfn.FORECAST.ETS(A19,$B$2:$B$17,$A$2:$A$17,1,1) -> 182596.94 | D19: =C19-_xlfn.FORECAST.ETS.CONFINT(A19,$B$2:$B$17,$A$2:$A$17,0.95,1,1) -> 102846.56 | E19: =C19+_xlfn.FORECAST.ETS.CONFINT(A19,$B$2:$B$17,$A$2:$A$17,0.95,1,1) -> 262347.32
A20: 46204 | C20: =_xlfn.FORECAST.ETS(A20,$B$2:$B$17,$A$2:$A$17,1,1) -> 180424.44 | D20: =C20-_xlfn.FORECAST.ETS.CONFINT(A20,$B$2:$B$17,$A$2:$A$17,0.95,1,1) -> 93009.8 | E20: =C20+_xlfn.FORECAST.ETS.CONFINT(A20,$B$2:$B$17,$A$2:$A$17,0.95,1,1) -> 267839.07
A21: 46235 | C21: =_xlfn.FORECAST.ETS(A21,$B$2:$B$17,$A$2:$A$17,1,1) -> 178251.93 | D21: =C21-_xlfn.FORECAST.ETS.CONFINT(A21,$B$2:$B$17,$A$2:$A$17,0.95,1,1) -> 83765.834 | E21: =C21+_xlfn.FORECAST.ETS.CONFINT(A21,$B$2:$B$17,$A$2:$A$17,0.95,1,1) -> 272738.04

Sheet Planilha7
A1: Linha do Tempo | B1: Valores | C1: Previsão | D1: Limite de Confiança Inferior | E1: Limite de Confiança Superior
A2: 45658 | B2: 217.89
A3: 45689 | B3: 7973.12
A4: 45717 | B4: 5366.17
A5: 45748 | B5: -20347.55
A6: 45778 | B6: 10741.17
A7: 45809 | B7: -13284.03
A8: 45839 | B8: 2867.78
A9: 45870 | B9: -641.37
A10: 45901 | B10: 8471.35
A11: 45931 | B11: -8746.69
A12: 45962 | B12: 402.92
A13: 45992 | B13: 71166.29
... A16: 46082 | B16: 2497.14
A17: 46113 | B17: -2426.66 | C17: -2426.66 | D17: -2426.66 | E17: -2426.66
A18: 46143 | C18: =_xlfn.FORECAST.ETS(A18,$B$2:$B$17,$A$2:$A$17,1,1) -> -3277.4478 | D18: =C18-_xlfn.FORECAST.ETS.CONFINT(A18,$B$2:$B$17,$A$2:$A$17,0.95,1,1) -> -51978.622 | E18: =C18+_xlfn.FORECAST.ETS.CONFINT(A18,$B$2:$B$17,$A$2:$A$17,0.95,1,1) -> 45423.726
A19: 46174 | C19: =_xlfn.FORECAST.ETS(A19,$B$2:$B$17,$A$2:$A$17,1,1) -> -3489.7571 | D19: =C19-_xlfn.FORECAST.ETS.CONFINT(A19,$B$2:$B$17,$A$2:$A$17,0.95,1,1) -> -52191.15 | E19: =C19+_xlfn.FORECAST.ETS.CONFINT(A19,$B$2:$B$17,$A$2:$A$17,0.95,1,1) -> 45211.636
A20: 46204 | C20: =_xlfn.FORECAST.ETS(A20,$B$2:$B$17,$A$2:$A$17,1,1) -> -3702.0665 | D20: =C20-_xlfn.FORECAST.ETS.CONFINT(A20,$B$2:$B$17,$A$2:$A$17,0.95,1,1) -> -52403.849 | E20: =C20+_xlfn.FORECAST.ETS.CONFINT(A20,$B$2:$B$17,$A$2:$A$17,0.95,1,1) -> 44999.716
A21: 46235 | C21: =_xlfn.FORECAST.ETS(A21,$B$2:$B$17,$A$2:$A$17,1,1) -> -3914.3758 | D21: =C21-_xlfn.FORECAST.ETS.CONFINT(A21,$B$2:$B$17,$A$2:$A$17,0.95,1,1) -> -52616.767 | E21: =C21+_xlfn.FORECAST.ETS.CONFINT(A21,$B$2:$B$17,$A$2:$A$17,0.95,1,1) -> 44788.015
A22: 46266 | C22: =_xlfn.FORECAST.ETS(A22,$B$2:$B$17,$A$2:$A$17,1,1) -> -4126.6852 | D22: =C22-_xlfn.FORECAST.ETS.CONFINT(A22,$B$2:$B$17,$A$2:$A$17,0.95,1,1) -> -52829.953 | E22: =C22+_xlfn.FORECAST.ETS.CONFINT(A22,$B$2:$B$17,$A$2:$A$17,0.95,1,1) -> 44576.583

Sheet Home
B1: FINANCEIRO | Q1: NFE
A4: =IF(C4="ANUAL",DATE(2026,1,1),DATE(2026,MATCH(C4,{"JANEIRO";"FEVEREIRO";"MARÇO";"ABRIL";"MAIO";"JUNHO";"JULHO";"AGOSTO";"SETEMBRO";"OUTUBRO";"NOVEMBRO";"DEZEMBRO"},0),1)) -> 46023 | B4: Mês | C4: Anual | P4: =IF(R4="ANUAL",DATE(2026,1,1),DATE(2026,MATCH(R4,{"JANEIRO";"FEVEREIRO";"MARÇO";"ABRIL";"MAIO";"JUNHO";"JULHO";"AGOSTO";"SETEMBRO";"OUTUBRO";"NOVEMBRO";"DEZEMBRO"},0),1)) -> 46023 | Q4: Mês | R4: Anual
A5: =IF(C4="ANUAL",DATE(2026,12,31),EOMONTH(DATE(2026,MATCH(C4,{"JANEIRO";"FEVEREIRO";"MARÇO";"ABRIL";"MAIO";"JUNHO";"JULHO";"AGOSTO";"SETEMBRO";"OUTUBRO";"NOVEMBRO";"DEZEMBRO"},0),1),0)) -> 46387 | P5: =IF(R4="ANUAL",DATE(2026,12,31),EOMONTH(DATE(2026,MATCH(R4,{"JANEIRO";"FEVEREIRO";"MARÇO";"ABRIL";"MAIO";"JUNHO";"JULHO";"AGOSTO";"SETEMBRO";"OUTUBRO";"NOVEMBRO";"DEZEMBRO"},0),1),0)) -> 46387
B7: MAX LED | Q7: MAX LED
B8: ENTRADAS TOTAIS | F8: SAIDAS TOTAIS | J8: TOTAL | Q8: ENTRADAS TOTAIS | U8: SAIDAS TOTAIS | Y8: TOTAL
B9: =SUMIFS('ENTRADAS - FIN - ilumi'!D:D,'ENTRADAS - FIN - ilumi'!A:A,">="&A4,'ENTRADAS - FIN - ilumi'!A:A,"<="&A5)+SUMIFS('Entradas- fin- import'!D:D,'Entradas- fin- import'!A:A,">="&A4,'Entradas- fin- import'!A:A,"<="&A5) -> 1086398.6 | F9: =SUMIFS('Saidas-fin-import'!D:D,'Saidas-fin-import'!A:A,">="&A4,'Saidas-fin-import'!A:A,"<="&A5)+SUMIFS('SAIDAS-FIN-ilumi'!D:D,'SAIDAS-FIN-ilumi'!A:A,">="&A4,'SAIDAS-FIN-ilumi'!A:A,"<="&A5) -> 1166871.2 | J9: =B9+D10-F9 -> -80472.59 | Q9: =SUMIFS('SAÍDA NFE ILUMI'!D:D,'SAÍDA NFE ILUMI'!A:A,">="&P4,'SAÍDA NFE ILUMI'!A:A,"<="&P5)+SUMIFS('Saídas-NFE-import'!D:D,'Saídas-NFE-import'!A:A,">="&P4,'Saídas-NFE-import'!A:A,"<="&P5) -> 1120588.9 | U9: =SUMIFS('Entradas-NFE-Import'!D:D,'Entradas-NFE-Import'!A:A,">="&P4,'Entradas-NFE-Import'!A:A,"<="&P5)+SUMIFS('ENTRADA NFE ILUMI'!D:D,'ENTRADA NFE ILUMI'!A:A,">="&P4,'ENTRADA NFE ILUMI'!A:A,"<="&P5) -> 624281.03 | Y9: =Q9-U9 -> 496307.84
B12: MAX LED ILUMINAÇÃO | Q12: MAX LED ILUMINAÇÃO
B13: ENTRADAS | F13: SAIDAS | J13: TOTAL | Q13: ENTRADAS | U13: SAIDAS | Y13: TOTAL
B14: =SUMIFS('ENTRADAS - FIN - ilumi'!D:D,'ENTRADAS - FIN - ilumi'!A:A,">="&A4,'ENTRADAS - FIN - ilumi'!A:A,"<="&A5) -> 810757.63 | F14: =SUMIFS('SAIDAS-FIN-ilumi'!D:D,'SAIDAS-FIN-ilumi'!A:A,">="&A4,'SAIDAS-FIN-ilumi'!A:A,"<="&A5) -> 830291.43 | J14: =B14+D15-F14 -> -19533.8 | Q14: =SUMIFS('SAÍDA NFE ILUMI'!D:D,'SAÍDA NFE ILUMI'!A:A,">="&P4,'SAÍDA NFE ILUMI'!A:A,"<="&P5) -> 805816.77 | U14: =SUMIFS('ENTRADA NFE ILUMI'!D:D,'ENTRADA NFE ILUMI'!A:A,">="&P4,'ENTRADA NFE ILUMI'!A:A,"<="&P5) -> 465723.83 | Y14: =Q14-U14 -> 340092.94
B17: MAX LED IMPORTAÇÃO | Q17: MAX LED IMPORTAÇÃO
B18: ENTRADAS | F18: SAIDAS | J18: TOTAL | Q18: ENTRADAS | U18: SAIDAS | Y18: TOTAL
B19: =SUMIFS('Entradas- fin- import'!D:D,'Entradas- fin- import'!A:A,">="&A4,'Entradas- fin- import'!A:A,"<="&A5) -> 275640.99 | F19: =SUMIFS('Saidas-fin-import'!D:D,'Saidas-fin-import'!A:A,">="&A4,'Saidas-fin-import'!A:A,"<="&A5) -> 336579.78 | J19: =B19+D20-F19 -> -60938.79 | Q19: =SUMIFS('Saídas-NFE-import'!D:D,'Saídas-NFE-import'!A:A,">="&P4,'Saídas-NFE-import'!A:A,"<="&P5) -> 314772.1 | U19: =SUMIFS('Entradas-NFE-Import'!D:D,'Entradas-NFE-Import'!A:A,">="&P4,'Entradas-NFE-Import'!A:A,"<="&P5) -> 158557.2 | Y19: =Q19-U19 -> 156214.9
B23: MAX LED ILUMINAÇÃO | H23: MAX LED IMPORTAÇÃO
B24: MÊS | C24: Receita | D24: Saida | E24: TOTAL | H24: MÊS | I24: Receita | J24: Saída | K24: TOTAL
B25: Janeiro | C25: =SUMIF('ENTRADAS - FIN - ilumi'!F:F,"Janeiro",'ENTRADAS - FIN - ilumi'!D:D) -> 132275.4 | D25: =SUMIF('SAIDAS-FIN-ilumi'!F:F,"Janeiro",'SAIDAS-FIN-ilumi'!D:D) -> 116350.31 | E25: =D15+C25-D25 -> 15925.09 | H25: Janeiro | I25: =SUMIF('Entradas- fin- import'!E:E,"Janeiro",'Entradas- fin- import'!D:D) -> 13593.52 | J25: =SUMIF('Saidas-fin-import'!E:E,"Janeiro",'Saidas-fin-import'!D:D) -> 74876.93 | K25: =I25-J25 -> -61283.41
B26: Fevereiro | C26: =SUMIF('ENTRADAS - FIN - ilumi'!F:F,"Fevereiro",'ENTRADAS - FIN - ilumi'!D:D) -> 126679.25 | D26: =SUMIF('SAIDAS-FIN-ilumi'!F:F,"FEVEREIRO",'SAIDAS-FIN-ilumi'!D:D) -> 133410.26 | E26: =D16+C26-D26 -> -6731.01 | H26: Fevereiro | I26: =SUMIF('Entradas- fin- import'!E:E,"FEVEREIRO",'Entradas- fin- import'!D:D) -> 37091.38 | J26: =SUMIF('Saidas-fin-import'!E:E,"FEVEREIRO",'Saidas-fin-import'!D:D) -> 44764.38 | K26: =I26-J26 -> -7673
B27: Março | C27: =SUMIF('ENTRADAS - FIN - ilumi'!F:F,"MARÇO",'ENTRADAS - FIN - ilumi'!D:D) -> 183424.12 | D27: =SUMIF('SAIDAS-FIN-ilumi'!F:F,"MARÇO",'SAIDAS-FIN-ilumi'!D:D) -> 192968.08 | E27: =D17+C27-D27 -> -9543.96 | H27: Março | I27: =SUMIF('Entradas- fin- import'!E:E,"MARÇO",'Entradas- fin- import'!D:D) -> 37723.49 | J27: =SUMIF('Saidas-fin-import'!E:E,"MARÇO",'Saidas-fin-import'!D:D) -> 35226.35 | K27: =I27-J27 -> 2497.14
B28: Abril | C28: =SUMIF('ENTRADAS - FIN - ilumi'!F:F,"Abril",'ENTRADAS - FIN - ilumi'!D:D) -> 214380.68 | D28: =SUMIF('SAIDAS-FIN-ilumi'!F:F,"ABRIL",'SAIDAS-FIN-ilumi'!D:D) -> 231574.3 | E28: =D18+C28-D28 -> -17193.62 | H28: Abril | I28: =SUMIF('Entradas- fin- import'!E:E,"ABRIL",'Entradas- fin- import'!D:D) -> 105609.12 | J28: =SUMIF('Saidas-fin-import'!E:E,"ABRIL",'Saidas-fin-import'!D:D) -> 108035.78 | K28: =I28-J28 -> -2426.66
B29: Maio | C29: =SUMIF('ENTRADAS - FIN - ilumi'!F:F,"Maio",'ENTRADAS - FIN - ilumi'!D:D) -> 153998.18 | D29: =SUMIF('SAIDAS-FIN-ilumi'!F:F,"MAIO",'SAIDAS-FIN-ilumi'!D:D) -> 155988.48 | E29: =D19+C29-D29 -> -1990.3 | H29: Maio | I29: =SUMIF('Entradas- fin- import'!E:E,"MAIO",'Entradas- fin- import'!D:D) -> 80008.32 | J29: =SUMIF('Saidas-fin-import'!E:E,"MAIO",'Saidas-fin-import'!D:D) -> 70645.67 | K29: =I29-J29 -> 9362.65
B30: Junho | C30: =SUMIF('ENTRADAS - FIN - ilumi'!F:F,"Junho",'ENTRADAS - FIN - ilumi'!D:D) -> 0 | D30: =SUMIF('SAIDAS-FIN-ilumi'!F:F,"JUNHO",'SAIDAS-FIN-ilumi'!D:D) -> 0 | E30: - | H30: Junho | I30: =SUMIF('Entradas- fin- import'!E:E,"JUNHO",'Entradas- fin- import'!D:D) -> 0 | J30: =SUMIF('Saidas-fin-import'!E:E,"JUNHO",'Saidas-fin-import'!D:D) -> 0 | K30: -
B31: Julho | C31: =SUMIF('ENTRADAS - FIN - ilumi'!F:F,"Julho",'ENTRADAS - FIN - ilumi'!D:D) -> 0 | D31: =SUMIF('SAIDAS-FIN-ilumi'!F:F,"JULHO",'SAIDAS-FIN-ilumi'!D:D) -> 0 | E31: - | H31: Julho | I31: =SUMIF('Entradas- fin- import'!E:E,"JULHO",'Entradas- fin- import'!D:D) -> 0 | J31: =SUMIF('Saidas-fin-import'!E:E,"JULHO",'Saidas-fin-import'!D:D) -> 0 | K31: -
B32: Agosto | C32: =SUMIF('ENTRADAS - FIN - ilumi'!F:F,"Agosto",'ENTRADAS - FIN - ilumi'!D:D) -> 0 | D32: =SUMIF('SAIDAS-FIN-ilumi'!F:F,"AGOSTO",'SAIDAS-FIN-ilumi'!D:D) -> 0 | E32: - | H32: Agosto | I32: =SUMIF('Entradas- fin- import'!E:E,"AGOSTO",'Entradas- fin- import'!D:D) -> 0 | J32: =SUMIF('Saidas-fin-import'!E:E,"AGOSTO",'Saidas-fin-import'!D:D) -> 0 | K32: -
B33: Setembro | C33: =SUMIF('ENTRADAS - FIN - ilumi'!F:F,"Setembro",'ENTRADAS - FIN - ilumi'!D:D) -> 0 | D33: =SUMIF('SAIDAS-FIN-ilumi'!F:F,"SETEMBRO",'SAIDAS-FIN-ilumi'!D:D) -> 0 | E33: - | H33: Setembro | I33: =SUMIF('Entradas- fin- import'!E:E,"SETEMBRO",'Entradas- fin- import'!D:D) -> 0 | J33: =SUMIF('Saidas-fin-import'!E:E,"SETEMBRO",'Saidas-fin-import'!D:D) -> 0 | K33: -
B34: Outubro | C34: =SUMIF('ENTRADAS - FIN - ilumi'!F:F,"Outubro",'ENTRADAS - FIN - ilumi'!D:D) -> 0 | D34: =SUMIF('SAIDAS-FIN-ilumi'!F:F,"OUTUBRO",'SAIDAS-FIN-ilumi'!D:D) -> 0 | E34: - | H34: Outubro | I34: =SUMIF('Entradas- fin- import'!E:E,"OUTUBRO",'Entradas- fin- import'!D:D) -> 0 | J34: =SUMIF('Saidas-fin-import'!E:E,"OUTUBRO",'Saidas-fin-import'!D:D) -> 0 | K34: -
B35: Novembro | C35: =SUMIF('ENTRADAS - FIN - ilumi'!F:F,"Novembro",'ENTRADAS - FIN - ilumi'!D:D) -> 0 | D35: =SUMIF('SAIDAS-FIN-ilumi'!F:F,"NOVEMBRO",'SAIDAS-FIN-ilumi'!D:D) -> 0 | E35: - | H35: Novembro | I35: =SUMIF('Entradas- fin- import'!E:E,"NVEMBRO",'Entradas- fin- import'!D:D) -> 0 | J35: =SUMIF('Saidas-fin-import'!E:E,"NOVEMBRO",'Saidas-fin-import'!D:D) -> 0 | K35: -
B36: Dezembro | C36: =SUMIF('ENTRADAS - FIN - ilumi'!F:F,"Dezembro",'ENTRADAS - FIN - ilumi'!D:D) -> 0 | D36: =SUMIF('SAIDAS-FIN-ilumi'!F:F,"DEZEMBRO",'SAIDAS-FIN-ilumi'!D:D) -> 0 | E36: - | H36: Dezembro | I36: =SUMIF('Entradas- fin- import'!E:E,"DEZEMBRO",'Entradas- fin- import'!D:D) -> 0 | J36: =SUMIF('Saidas-fin-import'!E:E,"DEZEMBRO",'Saidas-fin-import'!D:D) -> 0 | K36: -
B37: Total | C37: =SUM(C25:C36) -> 810757.63 | D37: =SUM(D25:D36) -> 830291.43 | E37: =SUM(E25:E28) -> -17543.5 | H37: Total | I37: =SUM(I25:I36) -> 274025.83 | J37: =SUM(J25:J36) -> 333549.11 | K37: =SUM(K25:K36) -> -59523.28
B54: Projeções Max Led Iluminação | H54: Projeções Max Led Importação
C55: Entradas | D55: Saidas | E55: Total | I55: Entradas | J55: Saidas | K55: Total
B56: 45658 | C56: 159260.53 | D56: 175562.16 | E56: =C56-D56 -> -16301.63 | H56: 45658 | I56: 19591.87 | J56: 19373.98 | K56: =I56-J56 -> 217.89
B57: 45689 | C57: 205465.7 | D57: 187413.04 | E57: =C57-D57 -> 18052.66 | H57: 45689 | I57: 57998.11 | J57: 50024.99 | K57: =I57-J57 -> 7973.12
B58: 45717 | C58: 212696.97 | D58: 235789.98 | E58: =C58-D58 -> -23093.01 | H58: 45717 | I58: 56487.68 | J58: 51121.51 | K58: =I58-J58 -> 5366.17
B59: 45748 | C59: 225882.05 | D59: 204028.74 | E59: =C59-D59 -> 21853.31 | H59: 45748 | I59: 61782.7 | J59: 82130.25 | K59: =I59-J59 -> -20347.55
B60: 45778 | C60: 252020.4 | D60: 225748.62 | E60: =C60-D60 -> 26271.78 | H60: 45778 | I60: 39163.78 | J60: 28422.61 | K60: =I60-J60 -> 10741.17
B61: 45809 | C61: 159826.26 | D61: 201481.58 | E61: =C61-D61 -> -41655.32 | H61: 45809 | I61: 17138.87 | J61: 30422.9 | K61: =I61-J61 -> -13284.03
B62: 45839 | C62: 205248.67 | D62: 214354.38 | E62: =C62-D62 -> -9105.71 | H62: 45839 | I62: 68605.59 | J62: 65737.81 | K62: =I62-J62 -> 2867.78
B63: 45870 | C63: 183735.51 | D63: 191802.78 | E63: =C63-D63 -> -8067.27 | H63: 45870 | I63: 84229.75 | J63: 84871.12 | K63: =I63-J63 -> -641.37
B64: 45901 | C64: 202938.1 | D64: 204295.82 | E64: =C64-D64 -> -1357.72 | H64: 45901 | I64: 126144.65 | J64: 117673.3 | K64: =I64-J64 -> 8471.35
B65: 45931 | C65: 178379.29 | D65: 167394.79 | E65: =C65-D65 -> 10984.5 | H65: 45931 | I65: 61637.75 | J65: 70384.44 | K65: =I65-J65 -> -8746.69
B66: 45962 | C66: 184310.95 | D66: 183155.39 | E66: =C66-D66 -> 1155.56 | H66: 45962 | I66: 58123.77 | J66: 57720.85 | K66: =I66-J66 -> 402.92
...

Sheet Planilha2
A1: Linha do Tempo | B1: Valores | C1: Previsão | D1: Limite de Confiança Inferior | E1: Limite de Confiança Superior
A2: 45658 | B2: -16301.63
A3: 45689 | B3: 18052.66
A4: 45717 | B4: -23093.01
A5: 45748 | B5: 21853.31
A6: 45778 | B6: 26271.78
A7: 45809 | B7: -41655.32
A8: 45839 | B8: -9105.71
A9: 45870 | B9: -8067.27
A10: 45901 | B10: -1357.72
A11: 45931 | B11: 10984.5
A12: 45962 | B12: 1155.56
A13: 45992 | B13: 19189.27
... A16: 46082 | B16: -9543.96
A17: 46113 | B17: -17193.62 | C17: -17193.62 | D17: -17193.62 | E17: -17193.62
A18: 46143 | C18: =_xlfn.FORECAST.ETS(A18,$B$2:$B$17,$A$2:$A$17,1,1) -> -3062.1006 | D18: =C18-_xlfn.FORECAST.ETS.CONFINT(A18,$B$2:$B$17,$A$2:$A$17,0.95,1,1) -> -43764.003 | E18: =C18+_xlfn.FORECAST.ETS.CONFINT(A18,$B$2:$B$17,$A$2:$A$17,0.95,1,1) -> 37639.802
A19: 46174 | C19: =_xlfn.FORECAST.ETS(A19,$B$2:$B$17,$A$2:$A$17,1,1) -> -2984.5892 | D19: =C19-_xlfn.FORECAST.ETS.CONFINT(A19,$B$2:$B$17,$A$2:$A$17,0.95,1,1) -> -44013.419 | E19: =C19+_xlfn.FORECAST.ETS.CONFINT(A19,$B$2:$B$17,$A$2:$A$17,0.95,1,1) -> 38044.241
A20: 46204 | C20: =_xlfn.FORECAST.ETS(A20,$B$2:$B$17,$A$2:$A$17,1,1) -> -2907.0778 | D20: =C20-_xlfn.FORECAST.ETS.CONFINT(A20,$B$2:$B$17,$A$2:$A$17,0.95,1,1) -> -44265.358 | E20: =C20+_xlfn.FORECAST.ETS.CONFINT(A20,$B$2:$B$17,$A$2:$A$17,0.95,1,1) -> 38451.203
A21: 46235 | C21: =_xlfn.FORECAST.ETS(A21,$B$2:$B$17,$A$2:$A$17,1,1) -> -2829.5664 | D21: =C21-_xlfn.FORECAST.ETS.CONFINT(A21,$B$2:$B$17,$A$2:$A$17,0.95,1,1) -> -44519.8 | E21: =C21+_xlfn.FORECAST.ETS.CONFINT(A21,$B$2:$B$17,$A$2:$A$17,0.95,1,1) -> 38860.667
A22: 46266 | C22: =_xlfn.FORECAST.ETS(A22,$B$2:$B$17,$A$2:$A$17,1,1) -> -2752.0551 | D22: =C22-_xlfn.FORECAST.ETS.CONFINT(A22,$B$2:$B$17,$A$2:$A$17,0.95,1,1) -> -44776.725 | E22: =C22+_xlfn.FORECAST.ETS.CONFINT(A22,$B$2:$B$17,$A$2:$A$17,0.95,1,1) -> 39272.615
A23: 46296 | C23: =_xlfn.FORECAST.ETS(A23,$B$2:$B$17,$A$2:$A$17,1,1) -> -2674.5437 | D23: =C23-_xlfn.FORECAST.ETS.CONFINT(A23,$B$2:$B$17,$A$2:$A$17,0.95,1,1) -> -45036.113 | E23: =C23+_xlfn.FORECAST.ETS.CONFINT(A23,$B$2:$B$17,$A$2:$A$17,0.95,1,1) -> 39687.026

Sheet Planilha4
B3: Mês | C3: Entradas | D3: Saídas | E3: Resultado | F3: % da Receita | I3: Mês | J3: Entradas | K3: Saídas | L3: Resultado | M3: % da Receita | P3: Entradas | Q3: Saidas | R3: Total
B4: Janeiro | C4: R$ 19.591,87 | D4: R$ 19.373,98 | E4: R$ 217,89 | F4: 2.4% | I4: Janeiro | J4: R$ 159.260,53 | K4: R$ 175.562,16 | L4: -R$ 16.301,63 | M4: 6.7% | O4: 45658 | P4: 159260.53 | Q4: 175562.16 | R4: =P4-Q4 -> -16301.63 | S4: =_xlfn.PERCENTOF(P4,Q4) -> 0.90714611 | T4: 1.0188
B5: Fevereiro | C5: R$ 57.998,11 | D5: R$ 50.024,99 | E5: R$ 7.973,12 | F5: 7.2% | I5: Fevereiro | J5: R$ 205.465,70 | K5: R$ 187.413,04 | L5: R$ 18.052,66 | M5: 8.7% | O5: 45689 | P5: 205465.7 | Q5: 187413.04 | R5: =P5-Q5 -> 18052.66 | S5: =_xlfn.PERCENTOF(P5,Q5) -> 1.0963255
B6: Março | C6: R$ 56.487,68 | D6: R$ 51.121,51 | E6: R$ 5.366,17 | F6: 7.1% | I6: Março | J6: R$ 212.696,97 | K6: R$ 235.789,98 | L6: -R$ 23.093,01 | M6: 9.0% | O6: 45717 | P6: 212696.97 | Q6: 235789.98 | R6: =P6-Q6 -> -23093.01 | S6: =_xlfn.PERCENTOF(P6,Q6) -> 0.90206111
B7: Abril | C7: R$ 61.782,70 | D7: R$ 82.130,25 | E7: -R$ 20.347,55 | F7: 7.7% | I7: Abril | J7: R$ 225.882,05 | K7: R$ 204.028,74 | L7: R$ 21.853,31 | M7: 9.5% | O7: 45748 | P7: 225882.05 | Q7: 204028.74 | R7: =P7-Q7 -> 21853.31 | S7: =_xlfn.PERCENTOF(P7,Q7) -> 1.107109
B8: Maio | C8: R$ 39.163,78 | D8: R$ 28.422,61 | E8: R$ 10.741,17 | F8: 4.9% | I8: Maio | J8: R$ 252.020,40 | K8: R$ 225.748,62 | L8: R$ 26.271,78 | M8: 10.6% | O8: 45778 | P8: 252020.4 | Q8: 225748.62 | R8: =P8-Q8 -> 26271.78 | S8: =_xlfn.PERCENTOF(P8,Q8) -> 1.1163763
B9: Junho | C9: R$ 17.138,87 | D9: R$ 30.422,90 | E9: -R$ 13.284,03 | F9: 2.1% | I9: Junho | J9: R$ 159.826,26 | K9: R$ 201.481,58 | L9: -R$ 41.655,32 | M9: 6.7% | O9: 45809 | P9: 159826.26 | Q9: 201481.58 | R9: =P9-Q9 -> -41655.32 | S9: =_xlfn.PERCENTOF(P9,Q9) -> 0.79325495
B10: Julho | C10: R$ 68.605,59 | D10: R$ 65.737,81 | E10: R$ 2.867,78 | F10: 8.6% | I10: Julho | J10: R$ 205.248,67 | K10: R$ 214.354,38 | L10: -R$ 9.105,71 | M10: 8.7% | O10: 45839 | P10: 205248.67 | Q10: 214354.38 | R10: =P10-Q10 -> -9105.71 | S10: =_xlfn.PERCENTOF(P10,Q10) -> 0.9575203
B11: Agosto | C11: R$ 84.229,75 | D11: R$ 84.871,12 | E11: -R$ 641,37 | F11: 10.5% | I11: Agosto | J11: R$ 183.735,51 | K11: R$ 191.802,78 | L11: -R$ 8.067,27 | M11: 7.8% | O11: 45870 | P11: 183735.51 | Q11: 191802.78 | R11: =P11-Q11 -> -8067.27 | S11: =_xlfn.PERCENTOF(P11,Q11) -> 0.95793977
B12: Setembro | C12: R$ 126.144,65 | D12: R$ 117.673,30 | E12: R$ 8.471,35 | F12: 15.7% | I12: Setembro | J12: 202938.1 | K12: 204295.82 | L12: =J12-K12 -> -1357.72 | M12: 8.6% | O12: 45901 | P12: 202938.1 | Q12: 204295.82 | R12: =P12-Q12 -> -1357.72 | S12: =_xlfn.PERCENTOF(P12,Q12) -> 0.99335415
B13: Outubro | C13: R$ 61.637,75 | D13: R$ 70.384,44 | E13: -R$ 8.746,69 | F13: 7.7% | I13: Outubro | J13: 178.379,29 | K13: R$ 167.394,79 | L13: =J13-K13 -> #VALUE! | M13: 7.5% | O13: 45931 | P13: 178379.29 | Q13: 167394.79 | R13: =P13-Q13 -> 10984.5 | S13: =_xlfn.PERCENTOF(P13,Q13) -> 1.0656203
B14: Novembro | C14: R$ 58.123,77 | D14: R$ 57.720,85 | E14: R$ 402,92 | F14: 7.3% | I14: Novembro | J14: 184310.95 | K14: R$ 183.155,39 | L14: =J14-K14 -> #VALUE! | M14: 7.8% | O14: 45962 | P14: 184310.95 | Q14: 183155.39 | R14: =P14-Q14 -> 1155.56 | S14: =_xlfn.PERCENTOF(P14,Q14) -> 1.0063092
B15: Dezembro | C15: R$ 150.258,42 | D15: R$ 79.092,13 | E15: R$ 71.166,29 | F15: 18.8% | I15: Dezembro | J15: 198779.59 | K15: 179.590,32 | L15: =J15-K15 -> #VALUE! | M15: 8.4% | O15: 45992 | P15: 198779.59 | Q15: 179590.32 | R15: =P15-Q15 -> 19189.27 | S15: =_xlfn.PERCENTOF(P15,Q15) -> 1.1068502
I16: 46023 | J16: =SUMIF('ENTRADAS - FIN - ilumi'!F:F,"Janeiro",'ENTRADAS - FIN - ilumi'!D:D) -> 132275.4 | K16: =SUMIF('SAIDAS-FIN-ilumi'!F:F,"Janeiro",'SAIDAS-FIN-ilumi'!D:D) -> 116350.31 | L16: =D13+J16-K16 -> #VALUE! | M16: =IF(D13=0,0,(L16-D13)/D13) -> #VALUE! | O16: 46023 | P16: 132275.4 | Q16: 116350.31 | R16: =P16-Q16 -> 15925.09 | S16: =_xlfn.PERCENTOF(P16,Q16) -> 1.1368719
I17: 46054 | J17: =SUMIF('ENTRADAS - FIN - ilumi'!F:F,"Fevereiro",'ENTRADAS - FIN - ilumi'!D:D) -> 126679.25 | K17: =SUMIF('SAIDAS-FIN-ilumi'!F:F,"Fevereiro",'SAIDAS-FIN-ilumi'!D:D) -> 133410.26 | L17: =L16+J17-K17 -> #VALUE! | M17: =IF(D13=0,0,(L17-D13)/D13) -> #VALUE! | O17: 46054 | P17: 126679.25 | Q17: 133410.26 | R17: =P17-Q17 -> -6731.01 | S17: =_xlfn.PERCENTOF(P17,Q17) -> 0.94954653
I18: 46082 | J18: =SUMIF('ENTRADAS - FIN - ilumi'!F:F,"Março",'ENTRADAS - FIN - ilumi'!D:D) -> 183424.12 | K18: =SUMIF('SAIDAS-FIN-ilumi'!F:F,"Março",'SAIDAS-FIN-ilumi'!D:D) -> 192968.08 | L18: =L17+J18-K18 -> #VALUE! | M18: =IF(D13=0,0,(L18-D13)/D13) -> #VALUE! | O18: 46082 | P18: 183424.12 | Q18: 192968.08 | R18: =P18-Q18 -> -9543.96 | S18: =_xlfn.PERCENTOF(P18,Q18) -> 0.95054125
I19: 46113 | J19: =SUMIF('ENTRADAS - FIN - ilumi'!F:F,"Abril",'ENTRADAS - FIN - ilumi'!D:D) -> 214380.68 | K19: =SUMIF('SAIDAS-FIN-ilumi'!F:F,"Abril",'SAIDAS-FIN-ilumi'!D:D) -> 231574.3 | L19: =L18+J19-K19 -> #VALUE! | M19: =IF(D13=0,0,(L19-D13)/D13) -> #VALUE! | O19: 46113 | P19: 214380.68 | Q19: 231574.3 | R19: =P19-Q19 -> -17193.62 | S19: =_xlfn.PERCENTOF(P19,Q19) -> 0.92575333
C20: 19591.87 | D20: 19373.98 | E20: =C20-D20 -> 217.89 | O20: 46143 | P20: =_xlfn.FORECAST.LINEAR(O20,P8:P19,O8:O19)*1.083 -> 175445.05 | Q20: =AVERAGE(Q8:Q19) -> 186843.89 | R20: =P20-Q20 -> -11398.833 | S20: =_xlfn.PERCENTOF(P20,Q20) -> 0.93899274
C21: 57998.11 | D21: 50024.99 | E21: =C21-D21 -> 7973.12 | I21: 45658 | J21: =C20+P4 -> 178852.4 | K21: =D20+Q4 -> 194936.14 | L21: =J21-K21 -> -16083.74 | O21: 46174 | P21: =_xlfn.FORECAST.LINEAR(O21,P9:P20,O9:O20)*1.083 -> 187195.64 | Q21: =AVERAGE(Q9:Q20) -> 183601.82 | R21: =P21-Q21 -> 3593.8143 | S21: =_xlfn.PERCENTOF(P21,Q21) -> 1.019574
C22: 56487.68 | D22: 51121.51 | E22: =C22-D22 -> 5366.17 | I22: 45689 | J22: =C21+P5 -> 263463.81 | K22: =D21+Q5 -> 237438.03 | L22: =J22-K22 -> 26025.78 | O22: 46204 | P22: =_xlfn.FORECAST.LINEAR(O22,P10:P21,O10:O21)*1.083 -> 185870.74 | Q22: =AVERAGE(Q10:Q21) -> 182111.85 | R22: =P22-Q22 -> 3758.8907 | S22: =_xlfn.PERCENTOF(P22,Q22) -> 1.0206406
C23: 61782.7 | D23: 82130.25 | E23: =C23-D23 -> -20347.55 | I23: 45717 | J23: =C22+P6 -> 269184.65 | K23: =D22+Q6 -> 286911.49 | L23: =J23-K23 -> -17726.84 | O23: 46235 | P23: =_xlfn.FORECAST.LINEAR(O23,P11:P22,O11:O22)*1.083 -> 193165.15 | Q23: =AVERAGE(Q11:Q22) -> 179424.97 | R23: =P23-Q23 -> 13740.178 | S23: =_xlfn.PERCENTOF(P23,Q23) -> 1.076579
C24: 39163.78 | D24: 28422.61 | E24: =C24-D24 -> 10741.17 | I24: 45748 | J24: =C23+P7 -> 287664.75 | K24: =D23+Q7 -> 286158.99 | L24: =J24-K24 -> 1505.76
C25: 17138.87 | D25: 30422.9 | E25: =C25-D25 -> -13284.03 | I25: 45778 | J25: =C24+P8 -> 291184.18 | K25: =D24+Q8 -> 254171.23 | L25: =J25-K25 -> 37012.95
C26: 68605.59 | D26: 65737.81 | E26: =C26-D26 -> 2867.78 | I26: 45809 | J26: =C25+P9 -> 176965.13 | K26: =D25+Q9 -> 231904.48 | L26: =J26-K26 -> -54939.35
C27: 84229.75 | D27: 84871.12 | E27: =C27-D27 -> -641.37 | I27: 45839 | J27: =C26+P10 -> 273854.26 | K27: =D26+Q10 -> 280092.19 | L27: =J27-K27 -> -6237.93
C28: 126144.65 | D28: 117673.3 | E28: =C28-D28 -> 8471.35 | I28: 45870 | J28: =C27+P11 -> 267965.26 | K28: =D27+Q11 -> 276673.9 | L28: =J28-K28 -> -8708.64
C29: 61637.75 | D29: 70384.44 | E29: =C29-D29 -> -8746.69 | I29: 45901 | J29: =C28+P12 -> 329082.75 | K29: =D28+Q12 -> 321969.12 | L29: =J29-K29 -> 7113.63
C30: 58123.77 | D30: 57720.85 | E30: =C30-D30 -> 402.92 | I30: 45931 | J30: =C29+P13 -> 240017.04 | K30: =D29+Q13 -> 237779.23 | L30: =J30-K30 -> 2237.81
C31: 150258.42 | D31: 79092.13 | E31: =C31-D31 -> 71166.29 | I31: 45962 | J31: =C30+P14 -> 242434.72 | K31: =D30+Q14 -> 240876.24 | L31: =J31-K31 -> 1558.48
C32: 13593.52 | D32: 74876.93 | E32: =C32-D32 -> -61283.41 | I32: 45992 | J32: =C31+P15 -> 349038.01 | K32: =D31+Q15 -> 258682.45 | L32: =J32-K32 -> 90355.56
C33: 37091.38 | D33: 44764.38 | E33: =C33-D33 -> -7673 | I33: 46023 | J33: =C32+P16 -> 145868.92 | K33: =D32+Q16 -> 191227.24 | L33: =J33-K33 -> -45358.32
C34: 37723.49 | D34: 35226.35 | E34: =C34-D34 -> 2497.14 | I34: 46054 | J34: =C33+P17 -> 163770.63 | K34: =D33+Q17 -> 178174.64 | L34: =J34-K34 -> -14404.01
C35: 105609.12 | D35: 108035.78 | E35: =C35-D35 -> -2426.66 | I35: 46082 | J35: =C34+P18 -> 221147.61 | K35: =D34+Q18 -> 228194.43 | L35: =J35-K35 -> -7046.82
I36: 46113 | J36: =C35+P19 -> 319989.8 | K36: =D35+Q19 -> 339610.08 | L36: =J36-K36 -> -19620.28
I37: 46143 | J37: =_xlfn.FORECAST.LINEAR(I37,J21:J36,I21:I36)*1.083 -> 269520.26 | K37: =AVERAGE(K21:K36) -> 252799.99 | L37: =J37-K37 -> 16720.268
I38: 46174 | J38: =_xlfn.FORECAST.LINEAR(I38,J22:J37,I22:I37)*1.083 -> 262741.42 | K38: =AVERAGE(K22:K37) -> 256416.48 | L38: =J38-K38 -> 6324.9333
I39: 46204 | J39: =_xlfn.FORECAST.LINEAR(I39,J23:J38,I23:I38)*1.083 -> 265397.97 | K39: =AVERAGE(K23:K38) -> 257602.64 | L39: =J39-K39 -> 7795.3366
I40: 46235 | J40: =_xlfn.FORECAST.LINEAR(I40,J24:J39,I24:I39)*1.083 -> 269643.02 | K40: =AVERAGE(K24:K39) -> 255770.83 | L40: =J40-K40 -> 13872.19
I41: 46266 | J41: =_xlfn.FORECAST.LINEAR(I41,J25:J40,I25:I40)*1.083 -> 278206.61 | K41: =AVERAGE(K25:K40) -> 253871.57 | L41: =J41-K41 -> 24335.037

Sheet Planilha5
A1: Linha do Tempo | B1: Valores | C1: Previsão | D1: Limite de Confiança Inferior | E1: Limite de Confiança Superior
A2: 45658 | B2: 178852.4
A3: 45689 | B3: 263463.81
A4: 45717 | B4: 269184.65
A5: 45748 | B5: 287664.75
A6: 45778 | B6: 291184.18
A7: 45809 | B7: 176965.13
A8: 45839 | B8: 273854.26
A9: 45870 | B9: 267965.26
A10: 45901 | B10: 329082.75
A11: 45931 | B11: 240017.04
A12: 45962 | B12: 242434.72
A13: 45992 | B13: 349038.01
... A16: 46082 | B16: 221147.61
A17: 46113 | B17: 319989.8 | C17: 319989.8 | D17: 319989.8 | E17: 319989.8
A18: 46143 | C18: =_xlfn.FORECAST.ETS(A18,$B$2:$B$17,$A$2:$A$17,1,1) -> 263468.53 | D18: =C18-_xlfn.FORECAST.ETS.CONFINT(A18,$B$2:$B$17,$A$2:$A$17,0.95,1,1) -> 121874.18 | E18: =C18+_xlfn.FORECAST.ETS.CONFINT(A18,$B$2:$B$17,$A$2:$A$17,0.95,1,1) -> 405062.88
A19: 46174 | C19: =_xlfn.FORECAST.ETS(A19,$B$2:$B$17,$A$2:$A$17,1,1) -> 263381.68 | D19: =C19-_xlfn.FORECAST.ETS.CONFINT(A19,$B$2:$B$17,$A$2:$A$17,0.95,1,1) -> 105011.01 | E19: =C19+_xlfn.FORECAST.ETS.CONFINT(A19,$B$2:$B$17,$A$2:$A$17,0.95,1,1) -> 421752.35
A20: 46204 | C20: =_xlfn.FORECAST.ETS(A20,$B$2:$B$17,$A$2:$A$17,1,1) -> 263294.83 | D20: =C20-_xlfn.FORECAST.ETS.CONFINT(A20,$B$2:$B$17,$A$2:$A$17,0.95,1,1) -> 89704.259 | E20: =C20+_xlfn.FORECAST.ETS.CONFINT(A20,$B$2:$B$17,$A$2:$A$17,0.95,1,1) -> 436885.41
A21: 46235 | C21: =_xlfn.FORECAST.ETS(A21,$B$2:$B$17,$A$2:$A$17,1,1) -> 263207.98 | D21: =C21-_xlfn.FORECAST.ETS.CONFINT(A21,$B$2:$B$17,$A$2:$A$17,0.95,1,1) -> 75574.685 | E21: =C21+_xlfn.FORECAST.ETS.CONFINT(A21,$B$2:$B$17,$A$2:$A$17,0.95,1,1) -> 450841.28

Sheet Max Led Consolidada
A1: Max Led consolidada
A4: DRE Financeiro | D4: Período Inicial: | E4: =IF(B8="ANUAL",DATE(2026,1,1),DATE(2026,MATCH(B8,{"JANEIRO";"FEVEREIRO";"MARÇO";"ABRIL";"MAIO";"JUNHO";"JULHO";"AGOSTO";"SETEMBRO";"OUTUBRO";"NOVEMBRO";"DEZEMBRO"},0),1)) -> 46143 | H4: DRE NFE | L4: Período Inicial: | M4: =IF(I8="ANUAL",DATE(2026,1,1),DATE(2026,MATCH(I8,{"JANEIRO";"FEVEREIRO";"MARÇO";"ABRIL";"MAIO";"JUNHO";"JULHO";"AGOSTO";"SETEMBRO";"OUTUBRO";"NOVEMBRO";"DEZEMBRO"},0),1)) -> 46023 | R4: Previsões financeiro Max Led Conjunto
D5: Período Final: | E5: =IF(B8="ANUAL",DATE(2026,12,31),EOMONTH(DATE(2026,MATCH(B8,{"JANEIRO";"FEVEREIRO";"MARÇO";"ABRIL";"MAIO";"JUNHO";"JULHO";"AGOSTO";"SETEMBRO";"OUTUBRO";"NOVEMBRO";"DEZEMBRO"},0),1),0)) -> 46173 | L5: Período Final: | M5: =IF(I8="ANUAL",DATE(2026,12,31),EOMONTH(DATE(2026,MATCH(I8,{"JANEIRO";"FEVEREIRO";"MARÇO";"ABRIL";"MAIO";"JUNHO";"JULHO";"AGOSTO";"SETEMBRO";"OUTUBRO";"NOVEMBRO";"DEZEMBRO"},0),1),0)) -> 46387 | S5: Receita | T5: Saidas | U5: Total | X5: Mês | Y5: A Receber Iluminação | Z5: A Pagar Iluminação | AA5: Saldo
R6: 45658 | S6: 178852.4 | T6: 194936.14 | U6: -16083.74 | X6: mai/26 | Y6: {=SUMPRODUCT((MID('[1]A receer iluminação'!$E$2:$E$271,4,2)="05")*(MID('[1]A receer iluminação'!$E$2:$E$271,7,4)="2026")*('[1]A receer iluminação'!$D$2:$D$271))} -> 160141.83 | Z6: {=SUMPRODUCT((MID('[1]a pagar iluminação'!$G$2:$G$384,4,2)="05")*(MID('[1]a pagar iluminação'!$G$2:$G$384,7,4)="2026")*('[1]a pagar iluminação'!$F$2:$F$384))} -> 154894.47 | AA6: =Y6-Z6 -> 5247.36
D7: RECEITA BRUTA | E7: =SUMIFS('ENTRADAS - FIN - ilumi'!D:D,'ENTRADAS - FIN - ilumi'!A:A,">="&E4,'ENTRADAS - FIN - ilumi'!A:A,"<="&E5)+SUMIFS('Entradas- fin- import'!D:D,'Entradas- fin- import'!A:A,">="&E4,'Entradas- fin- import'!A:A,"<="&E5) -> 234006.5 | L7: RECEITA BRUTA | M7: =SUMIFS('SAÍDA NFE ILUMI'!D:D,'SAÍDA NFE ILUMI'!A:A,">="&M4,'SAÍDA NFE ILUMI'!A:A,"<="&M5)+SUMIFS('Saídas-NFE-import'!D:D,'Saídas-NFE-import'!A:A,">="&M4,'Saídas-NFE-import'!A:A,"<="&M5) -> 1120588.9 | R7: 45689 | S7: 263463.81 | T7: 237438.03 | U7: 26025.78 | X7: jun/26 | Y7: {=SUMPRODUCT((MID('[1]A receer iluminação'!$E$2:$E$271,4,2)="06")*(MID('[1]A receer iluminação'!$E$2:$E$271,7,4)="2026")*('[1]A receer iluminação'!$D$2:$D$271))} -> 103947.86 | Z7: {=SUMPRODUCT((MID('[1]a pagar iluminação'!$G$2:$G$384,4,2)="06")*(MID('[1]a pagar iluminação'!$G$2:$G$384,7,4)="2026")*('[1]a pagar iluminação'!$F$2:$F$384))} -> 105849.64 | AA7: =Y7-Z7 -> -1901.78
A8: Mês | B8: Maio | D8: (-) IMPOSTOS (Simples Nacional) | E8: =SUMIFS('SAIDAS-FIN-ilumi'!D:D,'SAIDAS-FIN-ilumi'!C:C,"IMPOSTOS",'SAIDAS-FIN-ilumi'!A:A,">="&E4,'SAIDAS-FIN-ilumi'!A:A,"<="&E5)+SUMIFS('Saidas-fin-import'!D:D,'Saidas-fin-import'!C:C,"IMPOSTOS",'Saidas-fin-import'!A:A,">="&E4,'Saidas-fin-import'!A:A,"<="&E5) -> 21474.37 | H8: Mês | I8: Anual | L8: RECEITA SNF | M8: =SUMIFS('SAÍDA NFE ILUMI'!I:I,'SAÍDA NFE ILUMI'!J:J,"SNF",'SAÍDA NFE ILUMI'!F:F,">="&M4,'SAÍDA NFE ILUMI'!F:F,"<="&M5)+SUMIFS('Saídas-NFE-import'!D:D,'Saídas-NFE-import'!E:E,"SNF",'Saídas-NFE-import'!A:A,">="&M4,'Saídas-NFE-import'!A:A,"<="&M5) -> 23074.52 | R8: 45717 | S8: 269184.65 | T8: 286911.49 | U8: -17726.84 | X8: jul/26 | Y8: {=SUMPRODUCT((MID('[1]A receer iluminação'!$E$2:$E$271,4,2)="07")*(MID('[1]A receer iluminação'!$E$2:$E$271,7,4)="2026")*('[1]A receer iluminação'!$D$2:$D$271))} -> 25437.6 | Z8: {=SUMPRODUCT((MID('[1]a pagar iluminação'!$G$2:$G$384,4,2)="07")*(MID('[1]a pagar iluminação'!$G$2:$G$384,7,4)="2026")*('[1]a pagar iluminação'!$F$2:$F$384))} -> 55832.64 | AA8: =Y8-Z8 -> -30395.04
D9: RECEITA LÍQUIDA | E9: =E7-E8 -> 212532.13 | L9: Total de Receitas | M9: =M7+M8 -> 1143663.4 | R9: 45748 | S9: 287664.75 | T9: 286158.99 | U9: 1505.76 | X9: ago/26 | Y9: {=SUMPRODUCT((MID('[1]A receer iluminação'!$E$2:$E$271,4,2)="08")*(MID('[1]A receer iluminação'!$E$2:$E$271,7,4)="2026")*('[1]A receer iluminação'!$D$2:$D$271))} -> 3883.53 | Z9: {=SUMPRODUCT((MID('[1]a pagar iluminação'!$G$2:$G$384,4,2)="08")*(MID('[1]a pagar iluminação'!$G$2:$G$384,7,4)="2026")*('[1]a pagar iluminação'!$F$2:$F$384))} -> 51118.63 | AA9: =Y9-Z9 -> -47235.1
L10: (-) IMPOSTOS (Simples Nacional) | M10: =M7*0.1 -> 112058.89 | R10: 45778 | S10: 291184.18 | T10: 254171.23 | U10: 37012.95 | X10: set/26 | Y10: {=SUMPRODUCT((MID('[1]A receer iluminação'!$E$2:$E$271,4,2)="09")*(MID('[1]A receer iluminação'!$E$2:$E$271,7,4)="2026")*('[1]A receer iluminação'!$D$2:$D$271))} -> 0 | Z10: {=SUMPRODUCT((MID('[1]a pagar iluminação'!$G$2:$G$384,4,2)="09")*(MID('[1]a pagar iluminação'!$G$2:$G$384,7,4)="2026")*('[1]a pagar iluminação'!$F$2:$F$384))} -> 51118.63 | AA10: =Y10-Z10 -> -51118.63
D11: (-) CUSTO DAS MERCADORIAS (FORNECEDORES) | E11: =SUMIFS('SAIDAS-FIN-ilumi'!D:D,'SAIDAS-FIN-ilumi'!C:C,"FORNECEDORES",'SAIDAS-FIN-ilumi'!A:A,">="&E4,'SAIDAS-FIN-ilumi'!A:A,"<="&E5)+SUMIFS('Saidas-fin-import'!D:D,'Saidas-fin-import'!C:C,"FORNECEDORES",'Saidas-fin-import'!A:A,">="&E4,'Saidas-fin-import'!A:A,"<="&E5) -> 110059.13 | L11: RECEITA LÍQUIDA | M11: =M9-M10 -> 1031604.5 | R11: 45809 | S11: 176965.13 | T11: 231904.48 | U11: -54939.35 | X11: TOTAL | Y11: =SUM(Y6:Y10) -> 293410.82 | Z11: =SUM(Z6:Z10) -> 418814.01 | AA11: =Y11-Z11 -> -125403.19
A12: Total | B12: =B15-B18+B23 -> 115480 | D12: LUCRO BRUTO | E12: =E9-E11 -> 102473 | H12: Total | I12: =I15-I18 -> 496307.84 | R12: 45839 | S12: 273854.26 | T12: 280092.19 | U12: -6237.93
L13: (-) CUSTO DAS MERCADORIAS (FORNECEDORES) | M13: =SUMIFS('ENTRADA NFE ILUMI'!D:D,'ENTRADA NFE ILUMI'!A:A,">="&M4,'ENTRADA NFE ILUMI'!A:A,"<="&M5)+SUMIFS('Entradas-NFE-Import'!D:D,'Entradas-NFE-Import'!A:A,">="&M4,'Entradas-NFE-Import'!A:A,"<="&M5) -> 624281.03 | R13: 45870 | S13: 267965.26 | T13: 276673.9 | U13: -8708.64 | X13: Mês | Y13: A Receber Importação | Z13: A Pagar Importação | AA13: Saldo
D14: DESPESAS OPERACIONAIS: | L14: LUCRO BRUTO | M14: =M11-M13 -> 407323.47 | R14: 45901 | S14: 329082.75 | T14: 321969.12 | U14: 7113.63 | X14: mai/26 | Y14: {=SUMPRODUCT((VALUE(MID('[1]a reverber importação'!$G$2:$G$40,4,2))=5)*(VALUE(MID('[1]a reverber importação'!$G$2:$G$40,7,4))=2026)*('[1]a reverber importação'!$F$2:$F$40))} -> 68690.63 | Z14: {=SUMPRODUCT((VALUE(MID('[1]a pagar importaçãp'!$G$2:$G$55,4,2))=5)*(VALUE(MID('[1]a pagar importaçãp'!$G$2:$G$55,7,4))=2026)*('[1]a pagar importaçãp'!$F$2:$F$55))} -> 18896.66 | AA14: =Y14-Z14 -> 49793.97
A15: Entrada | B15: =SUMIFS('ENTRADAS - FIN - ilumi'!D:D,'ENTRADAS - FIN - ilumi'!A:A,">="&E4,'ENTRADAS - FIN - ilumi'!A:A,"<="&E5)+SUMIFS('Entradas- fin- import'!D:D,'Entradas- fin- import'!A:A,">="&E4,'Entradas- fin- import'!A:A,"<="&E5) -> 234006.5 | D15: BANCO | E15: =SUMIFS('SAIDAS-FIN-ilumi'!D:D,'SAIDAS-FIN-ilumi'!C:C,"BANCO",'SAIDAS-FIN-ilumi'!A:A,">="&E4,'SAIDAS-FIN-ilumi'!A:A,"<="&E5)+SUMIFS('Saidas-fin-import'!D:D,'Saidas-fin-import'!C:C,"BANCO",'Saidas-fin-import'!A:A,">="&E4,'Saidas-fin-import'!A:A,"<="&E5) -> 892.9 | H15: VENDAS | I15: =SUMIFS('SAÍDA NFE ILUMI'!D:D,'SAÍDA NFE ILUMI'!A:A,">="&M4,'SAÍDA NFE ILUMI'!A:A,"<="&M5)+SUMIFS('Saídas-NFE-import'!D:D,'Saídas-NFE-import'!A:A,">="&M4,'Saídas-NFE-import'!A:A,"<="&M5) -> 1120588.9 | R15: 45931 | S15: 240017.04 | T15: 237779.23 | U15: 2237.81 | X15: 46199 | Y15: {=SUMPRODUCT((VALUE(MID('[1]a reverber importação'!$G$2:$G$40,4,2))=6)*(VALUE(MID('[1]a reverber importação'!$G$2:$G$40,7,4))=2026)*('[1]a reverber importação'!$F$2:$F$40))} -> 70252.61 | Z15: {=SUMPRODUCT((VALUE(MID('[1]a pagar importaçãp'!$G$2:$G$55,4,2))=6)*(VALUE(MID('[1]a pagar importaçãp'!$G$2:$G$55,7,4))=2026)*('[1]a pagar importaçãp'!$F$2:$F$55))} -> 25391.83 | AA15: =Y15-Z15 -> 44860.78
D16: BRINDES | E16: =SUMIFS('SAIDAS-FIN-ilumi'!D:D,'SAIDAS-FIN-ilumi'!C:C,"BRINDES",'SAIDAS-FIN-ilumi'!A:A,">="&E4,'SAIDAS-FIN-ilumi'!A:A,"<="&E5)+SUMIFS('Saidas-fin-import'!D:D,'Saidas-fin-import'!C:C,"BRINDES",'Saidas-fin-import'!A:A,">="&E4,'Saidas-fin-import'!A:A,"<="&E5) -> 0 | L16: DESPESAS OPERACIONAIS: | R16: 45962 | S16: 242434.72 | T16: 240876.24 | U16: 1558.48 | X16: 46229 | Y16: {=SUMPRODUCT((VALUE(MID('[1]a reverber importação'!$G$2:$G$40,4,2))=7)*(VALUE(MID('[1]a reverber importação'!$G$2:$G$40,7,4))=2026)*('[1]a reverber importação'!$F$2:$F$40))} -> 7431.23 | Z16: {=SUMPRODUCT((VALUE(MID('[1]a pagar importaçãp'!$G$2:$G$55,4,2))=7)*(VALUE(MID('[1]a pagar importaçãp'!$G$2:$G$55,7,4))=2026)*('[1]a pagar importaçãp'!$F$2:$F$55))} -> 21657.83 | AA16: =Y16-Z16 -> -14226.6
D17: CARTÃO DE CRÉDITO | E17: =SUMIFS('SAIDAS-FIN-ilumi'!D:D,'SAIDAS-FIN-ilumi'!C:C,"CARTÃO DE CRÉDITO",'SAIDAS-FIN-ilumi'!A:A,">="&E4,'SAIDAS-FIN-ilumi'!A:A,"<="&E5)+SUMIFS('Saidas-fin-import'!D:D,'Saidas-fin-import'!C:C,"CARTÃO DE CRÉDITO",'Saidas-fin-import'!A:A,">="&E4,'Saidas-fin-import'!A:A,"<="&E5) -> 12871.28 | L17: BANCO | M17: =SUMIFS('SAIDAS-FIN-ilumi'!D:D,'SAIDAS-FIN-ilumi'!C:C,"BANCO",'SAIDAS-FIN-ilumi'!A:A,">="&M4,'SAIDAS-FIN-ilumi'!A:A,"<="&M5)+SUMIFS('Saidas-fin-import'!D:D,'Saidas-fin-import'!C:C,"BANCO",'Saidas-fin-import'!A:A,">="&M4,'Saidas-fin-import'!A:A,"<="&M5) -> 2329.68 | R17: 45992 | S17: 349038.01 | T17: 258682.45 | U17: 90355.56 | X17: ago/26 | Y17: {=SUMPRODUCT((VALUE(MID('[1]a reverber importação'!$G$2:$G$40,4,2))=8)*(VALUE(MID('[1]a reverber importação'!$G$2:$G$40,7,4))=2026)*('[1]a reverber importação'!$F$2:$F$40))} -> 516.33 | Z17: {=SUMPRODUCT((VALUE(MID('[1]a pagar importaçãp'!$G$2:$G$55,4,2))=8)*(VALUE(MID('[1]a pagar importaçãp'!$G$2:$G$55,7,4))=2026)*('[1]a pagar importaçãp'!$F$2:$F$55))} -> 11438.66 | AA17: =Y17-Z17 -> -10922.33
A18: Saídas | B18: =SUMIFS('Saidas-fin-import'!D:D,'Saidas-fin-import'!A:A,">="&E4,'Saidas-fin-import'!A:A,"<="&E5)+SUMIFS('SAIDAS-FIN-ilumi'!D:D,'SAIDAS-FIN-ilumi'!A:A,">="&E4,'SAIDAS-FIN-ilumi'!A:A,"<="&E5) -> 226634.15 | D18: CONSUMO | E18: =SUMIFS('SAIDAS-FIN-ilumi'!D:D,'SAIDAS-FIN-ilumi'!C:C,"CONSUMO",'SAIDAS-FIN-ilumi'!A:A,">="&E4,'SAIDAS-FIN-ilumi'!A:A,"<="&E5)+SUMIFS('Saidas-fin-import'!D:D,'Saidas-fin-import'!C:C,"CONSUMO",'Saidas-fin-import'!A:A,">="&E4,'Saidas-fin-import'!A:A,"<="&E5) -> 180 | H18: COMPRAS | I18: =SUMIFS('Entradas-NFE-Import'!D:D,'Entradas-NFE-Import'!A:A,">="&M4,'Entradas-NFE-Import'!A:A,"<="&M5)+SUMIFS('ENTRADA NFE ILUMI'!D:D,'ENTRADA NFE ILUMI'!A:A,">="&M4,'ENTRADA NFE ILUMI'!A:A,"<="&M5) -> 624281.03 | L18: BRINDES | M18: =SUMIFS('SAIDAS-FIN-ilumi'!D:D,'SAIDAS-FIN-ilumi'!C:C,"BRINDES",'SAIDAS-FIN-ilumi'!A:A,">="&M4,'SAIDAS-FIN-ilumi'!A:A,"<="&M5)+SUMIFS('Saidas-fin-import'!D:D,'Saidas-fin-import'!C:C,"BRINDES",'Saidas-fin-import'!A:A,">="&M4,'Saidas-fin-import'!A:A,"<="&M5) -> 1327 | R18: 46023 | S18: 145868.92 | T18: 191227.24 | U18: -45358.32 | X18: set/26 | Y18: {=SUMPRODUCT((VALUE(MID('[1]a reverber importação'!$G$2:$G$40,4,2))=9)*(VALUE(MID('[1]a reverber importação'!$G$2:$G$40,7,4))=2026)*('[1]a reverber importação'!$F$2:$F$40))} -> 0 | Z18: {=SUMPRODUCT((VALUE(MID('[1]a pagar importaçãp'!$G$2:$G$55,4,2))=9)*(VALUE(MID('[1]a pagar importaçãp'!$G$2:$G$55,7,4))=2026)*('[1]a pagar importaçãp'!$F$2:$F$55))} -> 11438.66 | AA18: =Y18-Z18 -> -11438.66
D19: CONTABILIDADE | E19: =SUMIFS('SAIDAS-FIN-ilumi'!D:D,'SAIDAS-FIN-ilumi'!C:C,"CONTABILIDADE",'SAIDAS-FIN-ilumi'!A:A,">="&E4,'SAIDAS-FIN-ilumi'!A:A,"<="&E5)+SUMIFS('Saidas-fin-import'!D:D,'Saidas-fin-import'!C:C,"CONTABILIDADE",'Saidas-fin-import'!A:A,">="&E4,'Saidas-fin-import'!A:A,"<="&E5) -> 0 | L19: CARTÃO DE CRÉDITO | M19: =SUMIFS('SAIDAS-FIN-ilumi'!D:D,'SAIDAS-FIN-ilumi'!C:C,"CARTÃO DE CRÉDITO",'SAIDAS-FIN-ilumi'!A:A,">="&M4,'SAIDAS-FIN-ilumi'!A:A,"<="&M5)+SUMIFS('Saidas-fin-import'!D:D,'Saidas-fin-import'!C:C,"CARTÃO DE CRÉDITO",'Saidas-fin-import'!A:A,">="&M4,'Saidas-fin-import'!A:A,"<="&M5) -> 50110.21 | R19: 46054 | S19: 163770.63 | T19: 178174.64 | U19: -14404.01 | X19: TOTAL | Y19: =SUM(Y14:Y18) -> 146890.8 | Z19: =SUM(Z14:Z18) -> 88823.64 | AA19: =Y19-Z19 -> 58067.16
D20: DEVOLUÇÃO | E20: =SUMIFS('SAIDAS-FIN-ilumi'!D:D,'SAIDAS-FIN-ilumi'!C:C,"DEVOLUÇÃO",'SAIDAS-FIN-ilumi'!A:A,">="&E4,'SAIDAS-FIN-ilumi'!A:A,"<="&E5)+SUMIFS('Saidas-fin-import'!D:D,'Saidas-fin-import'!C:C,"DEVOLUÇÃO",'Saidas-fin-import'!A:A,">="&E4,'Saidas-fin-import'!A:A,"<="&E5) -> 0 | L20: CONSUMO | M20: =SUMIFS('SAIDAS-FIN-ilumi'!D:D,'SAIDAS-FIN-ilumi'!C:C,"CONSUMO",'SAIDAS-FIN-ilumi'!A:A,">="&M4,'SAIDAS-FIN-ilumi'!A:A,"<="&M5)+SUMIFS('Saidas-fin-import'!D:D,'Saidas-fin-import'!C:C,"CONSUMO",'Saidas-fin-import'!A:A,">="&M4,'Saidas-fin-import'!A:A,"<="&M5) -> 2063.89 | R20: 46082 | S20: 221147.61 | T20: 228194.43 | U20: -7046.82
A21: Saldo total 2025 ilu | B21: 34572.78 | D21: EMPRÉSTIMO CAPITAL DE GIRO ITAÚ | E21: =SUMIFS('SAIDAS-FIN-ilumi'!D:D,'SAIDAS-FIN-ilumi'!C:C,"EMPRÉSTIMO CAPITAL DE GIRO ITAÚ",'SAIDAS-FIN-ilumi'!A:A,">="&E4,'SAIDAS-FIN-ilumi'!A:A,"<="&E5)+SUMIFS('Saidas-fin-import'!D:D,'Saidas-fin-import'!C:C,"EMPRÉSTIMO CAPITAL DE GIRO ITAÚ",'Saidas-fin-import'!A:A,">="&E4,'Saidas-fin-import'!A:A,"<="&E5) -> 0 | L21: CONTABILIDADE | M21: =SUMIFS('SAIDAS-FIN-ilumi'!D:D,'SAIDAS-FIN-ilumi'!C:C,"CONTABILIDADE",'SAIDAS-FIN-ilumi'!A:A,">="&M4,'SAIDAS-FIN-ilumi'!A:A,"<="&M5)+SUMIFS('Saidas-fin-import'!D:D,'Saidas-fin-import'!C:C,"CONTABILIDADE",'Saidas-fin-import'!A:A,">="&M4,'Saidas-fin-import'!A:A,"<="&M5) -> 2500 | R21: 46113 | S21: 319989.8 | T21: 339610.08 | U21: -19620.28
A22: Saldo total 2025 imp | B22: 73534.87 | D22: EMPRÉSTIMO CAPITAL DE GIRO BRADESCO | E22: =SUMIFS('SAIDAS-FIN-ilumi'!D:D,'SAIDAS-FIN-ilumi'!C:C,"EMPRÉSTIMO CAPITAL DE GIRO BRADESCO",'SAIDAS-FIN-ilumi'!A:A,">="&E4,'SAIDAS-FIN-ilumi'!A:A,"<="&E5)+SUMIFS('Saidas-fin-import'!D:D,'Saidas-fin-import'!C:C,"EMPRÉSTIMO CAPITAL DE GIRO BRADESCO",'Saidas-fin-import'!A:A,">="&E4,'Saidas-fin-import'!A:A,"<="&E5) -> 6441.56 | L22: DEVOLUÇÃO | M22: =SUMIFS('SAIDAS-FIN-ilumi'!D:D,'SAIDAS-FIN-ilumi'!C:C,"DEVOLUÇÃO",'SAIDAS-FIN-ilumi'!A:A,">="&M4,'SAIDAS-FIN-ilumi'!A:A,"<="&M5)+SUMIFS('Saidas-fin-import'!D:D,'Saidas-fin-import'!C:C,"DEVOLUÇÃO",'Saidas-fin-import'!A:A,">="&M4,'Saidas-fin-import'!A:A,"<="&M5) -> 400 | R22: 46143 | S22: 269520.26 | T22: =252799.9925 -> 252799.99 | U22: 16720.268
B23: =B21+B22 -> 108107.65 | D23: EMPRÉSTIMO PRONAMP | E23: =SUMIFS('SAIDAS-FIN-ilumi'!D:D,'SAIDAS-FIN-ilumi'!C:C,"EMPRÉSTIMO PRONAMP",'SAIDAS-FIN-ilumi'!A:A,">="&E4,'SAIDAS-FIN-ilumi'!A:A,"<="&E5)+SUMIFS('Saidas-fin-import'!D:D,'Saidas-fin-import'!C:C,"EMPRÉSTIMO PRONAMP",'Saidas-fin-import'!A:A,">="&E4,'Saidas-fin-import'!A:A,"<="&E5) -> 3700.52 | L23: EMPRÉSTIMO CAPITAL DE GIRO ITAÚ | M23: =SUMIFS('SAIDAS-FIN-ilumi'!D:D,'SAIDAS-FIN-ilumi'!C:C,"EMPRÉSTIMO CAPITAL DE GIRO ITAÚ",'SAIDAS-FIN-ilumi'!A:A,">="&M4,'SAIDAS-FIN-ilumi'!A:A,"<="&M5)+SUMIFS('Saidas-fin-import'!D:D,'Saidas-fin-import'!C:C,"EMPRÉSTIMO CAPITAL DE GIRO ITAÚ",'Saidas-fin-import'!A:A,">="&M4,'Saidas-fin-import'!A:A,"<="&M5) -> 5103.49 | R23: 46174 | S23: 262741.42 | T23: 256416.48 | U23: 6324.9333
D24: FUNCIONÁRIOS | E24: =SUMIFS('SAIDAS-FIN-ilumi'!D:D,'SAIDAS-FIN-ilumi'!C:C,"FUNCIONÁRIOS",'SAIDAS-FIN-ilumi'!A:A,">="&E4,'SAIDAS-FIN-ilumi'!A:A,"<="&E5)+SUMIFS('Saidas-fin-import'!D:D,'Saidas-fin-import'!C:C,"FUNCIONÁRIOS",'Saidas-fin-import'!A:A,">="&E4,'Saidas-fin-import'!A:A,"<="&E5) -> 18141.22 | H24: Import | L24: EMPRÉSTIMO CAPITAL DE GIRO BRADESCO | M24: =SUMIFS('SAIDAS-FIN-ilumi'!D:D,'SAIDAS-FIN-ilumi'!C:C,"EMPRÉSTIMO CAPITAL DE GIRO BRADESCO",'SAIDAS-FIN-ilumi'!A:A,">="&M4,'SAIDAS-FIN-ilumi'!A:A,"<="&M5)+SUMIFS('Saidas-fin-import'!D:D,'Saidas-fin-import'!C:C,"EMPRÉSTIMO CAPITAL DE GIRO BRADESCO",'Saidas-fin-import'!A:A,">="&M4,'Saidas-fin-import'!A:A,"<="&M5) -> 31535 | R24: 46204 | S24: 265397.97 | T24: 257602.64 | U24: 7795.3366
A25: Import | D25: FUNCIONÁRIOS (VR) | E25: =SUMIFS('SAIDAS-FIN-ilumi'!D:D,'SAIDAS-FIN-ilumi'!C:C,"FUNCIONÁRIOS (VR)",'SAIDAS-FIN-ilumi'!A:A,">="&E4,'SAIDAS-FIN-ilumi'!A:A,"<="&E5)+SUMIFS('Saidas-fin-import'!D:D,'Saidas-fin-import'!C:C,"FUNCIONÁRIOS (VR)",'Saidas-fin-import'!A:A,">="&E4,'Saidas-fin-import'!A:A,"<="&E5) -> 560 | H25: Entrada Import | I25: =SUMIFS('Saídas-NFE-import'!D:D,'Saídas-NFE-import'!A:A,">="&M4,'Saídas-NFE-import'!A:A,"<="&M5) -> 314772.1 | L25: EMPRÉSTIMO PRONAMP | M25: =SUMIFS('SAIDAS-FIN-ilumi'!D:D,'SAIDAS-FIN-ilumi'!C:C,"EMPRÉSTIMO PRONAMP",'SAIDAS-FIN-ilumi'!A:A,">="&M4,'SAIDAS-FIN-ilumi'!A:A,"<="&M5)+SUMIFS('Saidas-fin-import'!D:D,'Saidas-fin-import'!C:C,"EMPRÉSTIMO PRONAMP",'Saidas-fin-import'!A:A,">="&M4,'Saidas-fin-import'!A:A,"<="&M5) -> 10862.02 | R25: 46235 | S25: 269643.02 | T25: 255770.83 | U25: 13872.19
A26: Entrada Import | B26: =SUMIFS('Entradas- fin- import'!D:D,'Entradas- fin- import'!A:A,">="&E4,'Entradas- fin- import'!A:A,"<="&E5) -> 80008.32 | D26: GASTOS FIXOS | E26: =SUMIFS('SAIDAS-FIN-ilumi'!D:D,'SAIDAS-FIN-ilumi'!C:C,"GASTOS FIXOS",'SAIDAS-FIN-ilumi'!A:A,">="&E4,'SAIDAS-FIN-ilumi'!A:A,"<="&E5)+SUMIFS('Saidas-fin-import'!D:D,'Saidas-fin-import'!C:C,"GASTOS FIXOS",'Saidas-fin-import'!A:A,">="&E4,'Saidas-fin-import'!A:A,"<="&E5) -> 6520.59 | H26: Saída Import | I26: =SUMIFS('Entradas-NFE-Import'!D:D,'Entradas-NFE-Import'!A:A,">="&M4,'Entradas-NFE-Import'!A:A,"<="&M5) -> 158557.2 | L26: FUNCIONÁRIOS | M26: =SUMIFS('SAIDAS-FIN-ilumi'!D:D,'SAIDAS-FIN-ilumi'!C:C,"FUNCIONÁRIOS",'SAIDAS-FIN-ilumi'!A:A,">="&M4,'SAIDAS-FIN-ilumi'!A:A,"<="&M5)+SUMIFS('Saidas-fin-import'!D:D,'Saidas-fin-import'!C:C,"FUNCIONÁRIOS",'Saidas-fin-import'!A:A,">="&M4,'Saidas-fin-import'!A:A,"<="&M5) -> 74538.89 | R26: 46266 | S26: 278206.61 | T26: 253871.57 | U26: 24335.037
A27: Saída Import | B27: =SUMIFS('Saidas-fin-import'!D:D,'Saidas-fin-import'!A:A,">="&E4,'Saidas-fin-import'!A:A,"<="&E5) -> 70645.67 | D27: IMPORTAÇÃO | E27: =SUMIFS('SAIDAS-FIN-ilumi'!D:D,'SAIDAS-FIN-ilumi'!C:C,"IMPORTAÇÃO",'SAIDAS-FIN-ilumi'!A:A,">="&E4,'SAIDAS-FIN-ilumi'!A:A,"<="&E5)+SUMIFS('Saidas-fin-import'!D:D,'Saidas-fin-import'!C:C,"IMPORTAÇÃO",'Saidas-fin-import'!A:A,">="&E4,'Saidas-fin-import'!A:A,"<="&E5) -> 3200 | H27: Total Import | I27: =I25-I26 -> 156214.9 | L27: FUNCIONÁRIOS (VR) | M27: =SUMIFS('SAIDAS-FIN-ilumi'!D:D,'SAIDAS-FIN-ilumi'!C:C,"FUNCIONÁRIOS (VR)",'SAIDAS-FIN-ilumi'!A:A,">="&M4,'SAIDAS-FIN-ilumi'!A:A,"<="&M5)+SUMIFS('Saidas-fin-import'!D:D,'Saidas-fin-import'!C:C,"FUNCIONÁRIOS (VR)",'Saidas-fin-import'!A:A,">="&M4,'Saidas-fin-import'!A:A,"<="&M5) -> 1560
A28: Total Import | B28: =B26-B27 -> 9362.65 | D28: INVESTIMENTO | E28: =SUMIFS('SAIDAS-FIN-ilumi'!D:D,'SAIDAS-FIN-ilumi'!C:C,"INVESTIMENTO",'SAIDAS-FIN-ilumi'!A:A,">="&E4,'SAIDAS-FIN-ilumi'!A:A,"<="&E5)+SUMIFS('Saidas-fin-import'!D:D,'Saidas-fin-import'!C:C,"INVESTIMENTO",'Saidas-fin-import'!A:A,">="&E4,'Saidas-fin-import'!A:A,"<="&E5) -> 0 | L28: GASTOS FIXOS | M28: =SUMIFS('SAIDAS-FIN-ilumi'!D:D,'SAIDAS-FIN-ilumi'!C:C,"GASTOS FIXOS",'SAIDAS-FIN-ilumi'!A:A,">="&M4,'SAIDAS-FIN-ilumi'!A:A,"<="&M5)+SUMIFS('Saidas-fin-import'!D:D,'Saidas-fin-import'!C:C,"GASTOS FIXOS",'Saidas-fin-import'!A:A,">="&M4,'Saidas-fin-import'!A:A,"<="&M5) -> 45679.28
D29: MANUTENÇÃO | E29: =SUMIFS('SAIDAS-FIN-ilumi'!D:D,'SAIDAS-FIN-ilumi'!C:C,"MANUTENÇÃO",'SAIDAS-FIN-ilumi'!A:A,">="&E4,'SAIDAS-FIN-ilumi'!A:A,"<="&E5)+SUMIFS('Saidas-fin-import'!D:D,'Saidas-fin-import'!C:C,"MANUTENÇÃO",'Saidas-fin-import'!A:A,">="&E4,'Saidas-fin-import'!A:A,"<="&E5) -> 1900 | H29: Iluminação | L29: IMPORTAÇÃO | M29: =SUMIFS('SAIDAS-FIN-ilumi'!D:D,'SAIDAS-FIN-ilumi'!C:C,"IMPORTAÇÃO",'SAIDAS-FIN-ilumi'!A:A,">="&M4,'SAIDAS-FIN-ilumi'!A:A,"<="&M5)+SUMIFS('Saidas-fin-import'!D:D,'Saidas-fin-import'!C:C,"IMPORTAÇÃO",'Saidas-fin-import'!A:A,">="&M4,'Saidas-fin-import'!A:A,"<="&M5) -> 58200
A30: Iluminação | D30: MARKETING | E30: =SUMIFS('SAIDAS-FIN-ilumi'!D:D,'SAIDAS-FIN-ilumi'!C:C,"MARKETING",'SAIDAS-FIN-ilumi'!A:A,">="&E4,'SAIDAS-FIN-ilumi'!A:A,"<="&E5)+SUMIFS('Saidas-fin-import'!D:D,'Saidas-fin-import'!C:C,"MARKETING",'Saidas-fin-import'!A:A,">="&E4,'Saidas-fin-import'!A:A,"<="&E5) -> 0 | H30: Entrada Iluminação | I30: =SUMIFS('SAÍDA NFE ILUMI'!D:D,'SAÍDA NFE ILUMI'!A:A,">="&M4,'SAÍDA NFE ILUMI'!A:A,"<="&M5) -> 805816.77 | L30: INVESTIMENTO | M30: =SUMIFS('SAIDAS-FIN-ilumi'!D:D,'SAIDAS-FIN-ilumi'!C:C,"INVESTIMENTO",'SAIDAS-FIN-ilumi'!A:A,">="&M4,'SAIDAS-FIN-ilumi'!A:A,"<="&M5)+SUMIFS('Saidas-fin-import'!D:D,'Saidas-fin-import'!C:C,"INVESTIMENTO",'Saidas-fin-import'!A:A,">="&M4,'Saidas-fin-import'!A:A,"<="&M5) -> 7306.14
A31: Entrada Iluminação | B31: =SUMIFS('ENTRADAS - FIN - ilumi'!D:D,'ENTRADAS - FIN - ilumi'!A:A,">="&E4,'ENTRADAS - FIN - ilumi'!A:A,"<="&E5) -> 153998.18 | D31: MATERIAL DE ESCRITÓRIO | E31: =SUMIFS('SAIDAS-FIN-ilumi'!D:D,'SAIDAS-FIN-ilumi'!C:C,"MATERIAL DE ESCRITÓRIO",'SAIDAS-FIN-ilumi'!A:A,">="&E4,'SAIDAS-FIN-ilumi'!A:A,"<="&E5)+SUMIFS('Saidas-fin-import'!D:D,'Saidas-fin-import'!C:C,"MATERIAL DE ESCRITÓRIO",'Saidas-fin-import'!A:A,">="&E4,'Saidas-fin-import'!A:A,"<="&E5) -> 0 | H31: Saída Iluminação | I31: =SUMIFS('ENTRADA NFE ILUMI'!D:D,'ENTRADA NFE ILUMI'!A:A,">="&M4,'ENTRADA NFE ILUMI'!A:A,"<="&M5) -> 465723.83 | L31: MANUTENÇÃO | M31: =SUMIFS('SAIDAS-FIN-ilumi'!D:D,'SAIDAS-FIN-ilumi'!C:C,"MANUTENÇÃO",'SAIDAS-FIN-ilumi'!A:A,">="&M4,'SAIDAS-FIN-ilumi'!A:A,"<="&M5)+SUMIFS('Saidas-fin-import'!D:D,'Saidas-fin-import'!C:C,"MANUTENÇÃO",'Saidas-fin-import'!A:A,">="&M4,'Saidas-fin-import'!A:A,"<="&M5) -> 3735 | R31: mai/26 | S31: =Y6+Y14 -> 228832.46 | T31: =Z6+Z14 -> 173791.13 | U31: =S31-T31 -> 55041.33
A32: Saída Iluminação | B32: =SUMIFS('SAIDAS-FIN-ilumi'!D:D,'SAIDAS-FIN-ilumi'!A:A,">="&E4,'SAIDAS-FIN-ilumi'!A:A,"<="&E5) -> 155988.48 | D32: MOVIMENTO | E32: =SUMIFS('SAIDAS-FIN-ilumi'!D:D,'SAIDAS-FIN-ilumi'!C:C,"MOVIMENTO",'SAIDAS-FIN-ilumi'!A:A,">="&E4,'SAIDAS-FIN-ilumi'!A:A,"<="&E5)+SUMIFS('Saidas-fin-import'!D:D,'Saidas-fin-import'!C:C,"MOVIMENTO",'Saidas-fin-import'!A:A,">="&E4,'Saidas-fin-import'!A:A,"<="&E5) -> 5521.36 | H32: Total Iluminação | I32: =I30-I31 -> 340092.94 | L32: MARKETING | M32: =SUMIFS('SAIDAS-FIN-ilumi'!D:D,'SAIDAS-FIN-ilumi'!C:C,"MARKETING",'SAIDAS-FIN-ilumi'!A:A,">="&M4,'SAIDAS-FIN-ilumi'!A:A,"<="&M5)+SUMIFS('Saidas-fin-import'!D:D,'Saidas-fin-import'!C:C,"MARKETING",'Saidas-fin-import'!A:A,">="&M4,'Saidas-fin-import'!A:A,"<="&M5) -> 2007 | R32: 46199 | S32: =Y7+Y15 -> 174200.47 | T32: =Z7+Z15 -> 131241.47 | U32: =S32-T32 -> 42959
A33: Total Iluminação | B33: =B31-B32 -> -1990.3 | D33: PUBLICIDADE | E33: =SUMIFS('SAIDAS-FIN-ilumi'!D:D,'SAIDAS-FIN-ilumi'!C:C,"PUBLICIDADE",'SAIDAS-FIN-ilumi'!A:A,">="&E4,'SAIDAS-FIN-ilumi'!A:A,"<="&E5)+SUMIFS('Saidas-fin-import'!D:D,'Saidas-fin-import'!C:C,"PUBLICIDADE",'Saidas-fin-import'!A:A,">="&E4,'Saidas-fin-import'!A:A,"<="&E5) -> 0 | G33: =(H38/H39) -> 3125 | L33: MATERIAL DE ESCRITÓRIO | M33: =SUMIFS('SAIDAS-FIN-ilumi'!D:D,'SAIDAS-FIN-ilumi'!C:C,"MATERIAL DE ESCRITÓRIO",'SAIDAS-FIN-ilumi'!A:A,">="&M4,'SAIDAS-FIN-ilumi'!A:A,"<="&M5)+SUMIFS('Saidas-fin-import'!D:D,'Saidas-fin-import'!C:C,"MATERIAL DE ESCRITÓRIO",'Saidas-fin-import'!A:A,">="&M4,'Saidas-fin-import'!A:A,"<="&M5) -> 1242 | R33: 46229 | S33: =Y8+Y16 -> 32868.83 | T33: =Z8+Z16 -> 77490.47 | U33: =S33-T33 -> -44621.64
D34: SEGURO DE EMPRÉSTIMO | E34: =SUMIFS('SAIDAS-FIN-ilumi'!D:D,'SAIDAS-FIN-ilumi'!C:C,"SEGURO DE EMPRÉSTIMO",'SAIDAS-FIN-ilumi'!A:A,">="&E4,'SAIDAS-FIN-ilumi'!A:A,"<="&E5)+SUMIFS('Saidas-fin-import'!D:D,'Saidas-fin-import'!C:C,"SEGURO DE EMPRÉSTIMO",'Saidas-fin-import'!A:A,">="&E4,'Saidas-fin-import'!A:A,"<="&E5) -> 109.79 | G34: =G33+(1+0.65*0.1075) -> 3126.0699 | L34: MOVIMENTO | M34: =SUMIFS('SAIDAS-FIN-ilumi'!D:D,'SAIDAS-FIN-ilumi'!C:C,"MOVIMENTO",'SAIDAS-FIN-ilumi'!A:A,">="&M4,'SAIDAS-FIN-ilumi'!A:A,"<="&M5)+SUMIFS('Saidas-fin-import'!D:D,'Saidas-fin-import'!C:C,"MOVIMENTO",'Saidas-fin-import'!A:A,">="&M4,'Saidas-fin-import'!A:A,"<="&M5) -> 77021.36 | R34: ago/26 | S34: =Y9+Y17 -> 4399.86 | T34: =Z9+Z17 -> 62557.29 | U34: =S34-T34 -> -58157.43
D35: SEGURO DE VIDA SÓCIO | E35: =SUMIFS('SAIDAS-FIN-ilumi'!D:D,'SAIDAS-FIN-ilumi'!C:C,"SEGURO DE VIDA SÓCIO",'SAIDAS-FIN-ilumi'!A:A,">="&E4,'SAIDAS-FIN-ilumi'!A:A,"<="&E5)+SUMIFS('Saidas-fin-import'!D:D,'Saidas-fin-import'!C:C,"SEGURO DE VIDA SÓCIO",'Saidas-fin-import'!A:A,">="&E4,'Saidas-fin-import'!A:A,"<="&E5) -> 969.71 | G35: Max Iluminação | L35: PUBLICIDADE | M35: =SUMIFS('SAIDAS-FIN-ilumi'!D:D,'SAIDAS-FIN-ilumi'!C:C,"PUBLICIDADE",'SAIDAS-FIN-ilumi'!A:A,">="&M4,'SAIDAS-FIN-ilumi'!A:A,"<="&M5)+SUMIFS('Saidas-fin-import'!D:D,'Saidas-fin-import'!C:C,"PUBLICIDADE",'Saidas-fin-import'!A:A,">="&M4,'Saidas-fin-import'!A:A,"<="&M5) -> 147 | R35: TOTAL | S35: =SUM(S31:S34) -> 440301.62 | T35: =SUM(T31:T34) -> 445080.36 | U35: =SUM(U31:U34) -> -4778.74
D36: SEGURO SÓCIO CARRO | E36: =SUMIFS('SAIDAS-FIN-ilumi'!D:D,'SAIDAS-FIN-ilumi'!C:C,"SEGURO SÓCIO CARRO",'SAIDAS-FIN-ilumi'!A:A,">="&E4,'SAIDAS-FIN-ilumi'!A:A,"<="&E5)+SUMIFS('Saidas-fin-import'!D:D,'Saidas-fin-import'!C:C,"SEGURO SÓCIO CARRO",'Saidas-fin-import'!A:A,">="&E4,'Saidas-fin-import'!A:A,"<="&E5) -> 0 | L36: SEGURO DE EMPRÉSTIMO | M36: =SUMIFS('SAIDAS-FIN-ilumi'!D:D,'SAIDAS-FIN-ilumi'!C:C,"SEGURO DE EMPRÉSTIMO",'SAIDAS-FIN-ilumi'!A:A,">="&M4,'SAIDAS-FIN-ilumi'!A:A,"<="&M5)+SUMIFS('Saidas-fin-import'!D:D,'Saidas-fin-import'!C:C,"SEGURO DE EMPRÉSTIMO",'Saidas-fin-import'!A:A,">="&M4,'Saidas-fin-import'!A:A,"<="&M5) -> 548.95
D37: SÓCIOS | E37: =SUMIFS('SAIDAS-FIN-ilumi'!D:D,'SAIDAS-FIN-ilumi'!C:C,"SÓCIOS",'SAIDAS-FIN-ilumi'!A:A,">="&E4,'SAIDAS-FIN-ilumi'!A:A,"<="&E5)+SUMIFS('Saidas-fin-import'!D:D,'Saidas-fin-import'!C:C,"SÓCIOS",'Saidas-fin-import'!A:A,">="&E4,'Saidas-fin-import'!A:A,"<="&E5) -> 16500 | G37: Capital de Giro Bradesco | I37: Capital de Giro Itaú | L37: SEGURO DE VIDA SÓCIO | M37: =SUMIFS('SAIDAS-FIN-ilumi'!D:D,'SAIDAS-FIN-ilumi'!C:C,"SEGURO DE VIDA SÓCIO",'SAIDAS-FIN-ilumi'!A:A,">="&M4,'SAIDAS-FIN-ilumi'!A:A,"<="&M5)+SUMIFS('Saidas-fin-import'!D:D,'Saidas-fin-import'!C:C,"SEGURO DE VIDA SÓCIO",'Saidas-fin-import'!A:A,">="&M4,'Saidas-fin-import'!A:A,"<="&M5) -> 2909.13 | T37: =T31/T22*0.1 -> 0.068746493
D38: TRANSPORTES | E38: =SUMIFS('SAIDAS-FIN-ilumi'!D:D,'SAIDAS-FIN-ilumi'!C:C,"TRANSPORTES",'SAIDAS-FIN-ilumi'!A:A,">="&E4,'SAIDAS-FIN-ilumi'!A:A,"<="&E5)+SUMIFS('Saidas-fin-import'!D:D,'Saidas-fin-import'!C:C,"TRANSPORTES",'Saidas-fin-import'!A:A,">="&E4,'Saidas-fin-import'!A:A,"<="&E5) -> 6186.68 | G38: Valor Total inicial | H38: 150000 | I38: Valor Total inicial | J38: 92187.62 | L38: SEGURO SÓCIO CARRO | M38: =SUMIFS('SAIDAS-FIN-ilumi'!D:D,'SAIDAS-FIN-ilumi'!C:C,"SEGURO SÓCIO CARRO",'SAIDAS-FIN-ilumi'!A:A,">="&M4,'SAIDAS-FIN-ilumi'!A:A,"<="&M5)+SUMIFS('Saidas-fin-import'!D:D,'Saidas-fin-import'!C:C,"SEGURO SÓCIO CARRO",'Saidas-fin-import'!A:A,">="&M4,'Saidas-fin-import'!A:A,"<="&M5) -> 1863.46
D39: TRANSPORTES IMPORTAÇÃO | E39: =SUMIFS('SAIDAS-FIN-ilumi'!D:D,'SAIDAS-FIN-ilumi'!C:C,"TRANSPORTES IMPORTAÇÃO",'SAIDAS-FIN-ilumi'!A:A,">="&E4,'SAIDAS-FIN-ilumi'!A:A,"<="&E5)+SUMIFS('Saidas-fin-import'!D:D,'Saidas-fin-import'!C:C,"TRANSPORTES IMPORTAÇÃO",'Saidas-fin-import'!A:A,">="&E4,'Saidas-fin-import'!A:A,"<="&E5) -> 883.39 | G39: Total de parcelas | H39: 48 | I39: Total de parcelas | J39: 48 | L39: SÓCIOS | M39: =SUMIFS('SAIDAS-FIN-ilumi'!D:D,'SAIDAS-FIN-ilumi'!C:C,"SÓCIOS",'SAIDAS-FIN-ilumi'!A:A,">="&M4,'SAIDAS-FIN-ilumi'!A:A,"<="&M5)+SUMIFS('Saidas-fin-import'!D:D,'Saidas-fin-import'!C:C,"SÓCIOS",'Saidas-fin-import'!A:A,">="&M4,'Saidas-fin-import'!A:A,"<="&M5) -> 90052.61
D40: PLANO DE SAÚDE | E40: =SUMIFS('SAIDAS-FIN-ilumi'!D:D,'SAIDAS-FIN-ilumi'!C:C,"PLANO DE SAÚDE",'SAIDAS-FIN-ilumi'!A:A,">="&E4,'SAIDAS-FIN-ilumi'!A:A,"<="&E5) -> 0 | G40: Parcelas pagas | H40: =COUNTIF('SAIDAS-FIN-ilumi'!B:B,"EMPRÉSTIMO CAPITAL DE GIRO BRADESCO")+41 -> 41 | I40: Parcelas pagas | J40: =COUNTIF('SAIDAS-FIN-ilumi'!C:C,"EMPRÉSTIMO CAPITAL DE GIRO ITAÚ")+2 -> 4 | L40: TRANSPORTES | M40: =SUMIFS('SAIDAS-FIN-ilumi'!D:D,'SAIDAS-FIN-ilumi'!C:C,"TRANSPORTES",'SAIDAS-FIN-ilumi'!A:A,">="&M4,'SAIDAS-FIN-ilumi'!A:A,"<="&M5)+SUMIFS('Saidas-fin-import'!D:D,'Saidas-fin-import'!C:C,"TRANSPORTES",'Saidas-fin-import'!A:A,">="&M4,'Saidas-fin-import'!A:A,"<="&M5) -> 29509.08
D41: Outras Despesas Operacionais | E41: =SUMIFS('SAIDAS-FIN-ilumi'!D:D,'SAIDAS-FIN-ilumi'!C:C,"OUTRAS DESPESAS",'SAIDAS-FIN-ilumi'!A:A,">="&E4,'SAIDAS-FIN-ilumi'!A:A,"<="&E5) -> 0 | G41: Valor Parcela c/ juros | H41: =G33+G34 -> 6251.0699 | I41: Valor Parcela c/ juros | J41: =(J38/J39)*(1+0.49%+10.75%) -> 2136.4481 | L41: TRANSPORTES IMPORTAÇÃO | M41: =SUMIFS('SAIDAS-FIN-ilumi'!D:D,'SAIDAS-FIN-ilumi'!C:C,"TRANSPORTES IMPORTAÇÃO",'SAIDAS-FIN-ilumi'!A:A,">="&M4,'SAIDAS-FIN-ilumi'!A:A,"<="&M5)+SUMIFS('Saidas-fin-import'!D:D,'Saidas-fin-import'!C:C,"TRANSPORTES IMPORTAÇÃO",'Saidas-fin-import'!A:A,">="&M4,'Saidas-fin-import'!A:A,"<="&M5) -> 4945.26
D42: Total Despesas Operacionais | E42: =SUM(E15:E41) -> 84579 | G42: Parcelas restantes | H42: =H39-H40 -> 7 | I42: Parcelas restantes | J42: =J39-J40 -> 44 | L42: Outras Despesas Operacionais | M42: =SUMIFS('SAIDAS-FIN-ilumi'!L:L,'SAIDAS-FIN-ilumi'!K:K,"OUTRAS DESPESAS",'SAIDAS-FIN-ilumi'!I:I,">="&M6,'SAIDAS-FIN-ilumi'!I:I,"<="&M7) -> 0
...

Sheet Resumo Mensal Ilumini
A1: Max Led Iluminação
I2: Receira de Dez. | J2: 34572.78
H3: Financeiro
A4: DRE Financeiro | D4: DRE NFE | H4: MÊS | I4: Receita | J4: Saida | K4: TOTAL c. Dez | L4: TOTAL c. Dez | M4: Evolução %
H5: 46023 | I5: =SUMIF('ENTRADAS - FIN - ilumi'!F:F,"Janeiro",'ENTRADAS - FIN - ilumi'!D:D) -> 132275.4 | J5: =SUMIF('SAIDAS-FIN-ilumi'!F:F,"Janeiro",'SAIDAS-FIN-ilumi'!D:D) -> 116350.31 | K5: =I5-J5 -> 15925.09 | L5: =I5-J5 -> 15925.09 | M5: =IF(J2=0,0,(L5-J2)/J2) -> -0.53937491
A6: Entradas Fin ilumi | B6: Saidas Fin Ilu | D6: Entradas ilu NFE | E6: Saidas ilu NFE | H6: 46054 | I6: =SUMIF('ENTRADAS - FIN - ilumi'!F:F,"Fevereiro",'ENTRADAS - FIN - ilumi'!D:D) -> 126679.25 | J6: =SUMIF('SAIDAS-FIN-ilumi'!F:F,"Fevereiro",'SAIDAS-FIN-ilumi'!D:D) -> 133410.26 | K6: =I6-J6 -> -6731.01 | L6: =I6-J6 -> -6731.01 | M6: =IF(J2=0,0,(L6-J2)/J2) -> -1.194691
H7: 46082 | I7: =SUMIF('ENTRADAS - FIN - ilumi'!F:F,"MARÇO",'ENTRADAS - FIN - ilumi'!D:D) -> 183424.12 | J7: =SUMIF('SAIDAS-FIN-ilumi'!F:F,"Março",'SAIDAS-FIN-ilumi'!D:D) -> 192968.08 | K7: =I7-J7 -> -9543.96 | L7: =I7-J7 -> -9543.96 | M7: =IF(J2=0,0,(L7-J2)/J2) -> -1.2760542
A8: Mês | B8: Anual | D8: Mês | E8: Anual | H8: 46113 | I8: =SUMIF('ENTRADAS - FIN - ilumi'!F:F,"Abril",'ENTRADAS - FIN - ilumi'!D:D) -> 214380.68 | J8: =SUMIF('SAIDAS-FIN-ilumi'!F:F,"Abril",'SAIDAS-FIN-ilumi'!D:D) -> 231574.3 | K8: =I8-J8 -> -17193.62 | L8: =I8-J8 -> -17193.62 | M8: =IF(J2=0,0,(L8-J2)/J2) -> -1.4973167
H9: 46143 | I9: =SUMIF('ENTRADAS - FIN - ilumi'!F:F,"Maio",'ENTRADAS - FIN - ilumi'!D:D) -> 153998.18 | J9: =SUMIF('SAIDAS-FIN-ilumi'!F:F,"Maio",'SAIDAS-FIN-ilumi'!D:D) -> 155988.48 | K9: =I9-J9 -> -1990.3 | L9: =I9-J9 -> -1990.3 | M9: =IF(I8=0,0,(I9-I8)/I8) -> -0.28166018
H10: 46174 | I10: =SUMIF('ENTRADAS - FIN - ilumi'!F:F,"Junho",'ENTRADAS - FIN - ilumi'!D:D) -> 0 | J10: =SUMIF('SAIDAS-FIN-ilumi'!F:F,"Junho ",'SAIDAS-FIN-ilumi'!D:D) -> 0 | K10: =I10-J10 -> 0 | L10: =I10-J10 -> 0 | M10: =IF(I9=0,0,(I10-I9)/I9) -> -1
A11: Entrada | B11: =SUMIFS('ENTRADAS - FIN - ilumi'!D:D,'ENTRADAS - FIN - ilumi'!A:A,">="&$B$22,'ENTRADAS - FIN - ilumi'!A:A,"<="&$B$23) -> 810757.63 | H11: 46204 | I11: =SUMIF('ENTRADAS - FIN - ilumi'!F:F,"Julho",'ENTRADAS - FIN - ilumi'!D:D) -> 0 | J11: =SUMIF('SAIDAS-FIN-ilumi'!F:F,"Julho",'SAIDAS-FIN-ilumi'!D:D) -> 0 | K11: =I11-J11 -> 0 | L11: =I11-J11 -> 0 | M11: =IF(I10=0,0,(I11-I10)/I10) -> 0
D12: Total | E12: =E15-E18 -> 340092.94 | H12: 46235 | I12: =SUMIF('ENTRADAS - FIN - ilumi'!F:F,"Agosto",'ENTRADAS - FIN - ilumi'!D:D) -> 0 | J12: =SUMIF('SAIDAS-FIN-ilumi'!F:F,"Agosto",'SAIDAS-FIN-ilumi'!D:D) -> 0 | K12: =I12-J12 -> 0 | L12: =I12-J12 -> 0 | M12: =IF(I11=0,0,(I12-I11)/I11) -> 0
A13: Saídas | B13: =SUMIFS('SAIDAS-FIN-ilumi'!D:D,'SAIDAS-FIN-ilumi'!A:A,">="&$B$22,'SAIDAS-FIN-ilumi'!A:A,"<="&$B$23) -> 830291.43 | H13: 46266 | I13: =SUMIF('ENTRADAS - FIN - ilumi'!F:F,"Setembro",'ENTRADAS - FIN - ilumi'!D:D) -> 0 | J13: =SUMIF('SAIDAS-FIN-ilumi'!F:F,"Setembro",'SAIDAS-FIN-ilumi'!D:D) -> 0 | K13: =I13-J13 -> 0 | L13: =I13-J13 -> 0 | M13: =IF(I12=0,0,(I13-I12)/I12) -> 0
H14: 46296 | I14: =SUMIF('ENTRADAS - FIN - ilumi'!F:F,"Outubro",'ENTRADAS - FIN - ilumi'!D:D) -> 0 | J14: =SUMIF('SAIDAS-FIN-ilumi'!F:F,"Outubro",'SAIDAS-FIN-ilumi'!D:D) -> 0 | K14: =I14-J14 -> 0 | L14: =I14-J14 -> 0 | M14: =IF(I13=0,0,(I14-I13)/I13) -> 0
A15: Total | B15: =B11-B13 -> -19533.8 | D15: VENDAS | E15: =SUMIFS('SAÍDA NFE ILUMI'!D:D,'SAÍDA NFE ILUMI'!A:A,">="&$E$22,'SAÍDA NFE ILUMI'!A:A,"<="&$E$23) -> 805816.77 | H15: 46327 | I15: =SUMIF('ENTRADAS - FIN - ilumi'!F:F,"Novembro",'ENTRADAS - FIN - ilumi'!D:D) -> 0 | J15: =SUMIF('SAIDAS-FIN-ilumi'!F:F,"Novembro",'SAIDAS-FIN-ilumi'!D:D) -> 0 | K15: =I15-J15 -> 0 | L15: =I15-J15 -> 0 | M15: =IF(I14=0,0,(I15-I14)/I14) -> 0
H16: 46357 | I16: =SUMIF('ENTRADAS - FIN - ilumi'!F:F,"Dezembro",'ENTRADAS - FIN - ilumi'!D:D) -> 0 | J16: =SUMIF('SAIDAS-FIN-ilumi'!F:F,"Dezembro",'SAIDAS-FIN-ilumi'!D:D) -> 0 | K16: =I16-J16 -> 0 | L16: =I16-J16 -> 0 | M16: =IF(I15=0,0,(I16-I15)/I15) -> 0
H17: Total | I17: =SUM(I5:I16) -> 810757.63 | J17: =SUM(J5:J16) -> 830291.43 | K17: =SUM(K5:K16) -> -19533.8 | L17: =SUM(L5:L16) -> -19533.8
A18: Receira de Dez. | B18: 34572.78 | D18: COMPRAS | E18: =SUMIFS('ENTRADA NFE ILUMI'!D:D,'ENTRADA NFE ILUMI'!A:A,">="&$E$22,'ENTRADA NFE ILUMI'!A:A,"<="&$E$23) -> 465723.83
A19: Total com dezembro | B19: =B11+B18-B13 -> 15038.98 | H19: Projeções de Receita
H20: 46143 | I20: =_xlfn.FORECAST.LINEAR(H20,I5:I8,H5:H8) -> 239986.22
H21: 46174 | I21: =_xlfn.FORECAST.LINEAR(H21,I5:I8,H5:H8) -> 271315.39
